Workbook

Sheet Summary Data
A1: Comments and Notes | D1: Year | E1: Population Estimate | F1: Peak Count | G1: Annual AUC (fish days) | H1: OE Adj Peak / population ratio | I1: Survey 1 | M1: Survey 2 | R1: Survey 3 | W1: Survey 4 | AB1: Survey 5 | AG1: Survey 6 | AL1: Survey 7 | AQ1: Survey 8
I2: Observer Estimate | J2: Corrected Observer Estimate | K2: Date | L2: Stat. Day | M2: Observer Estimate | N2: Corrected Observer Estimate | O2: Date | P2: Stat. Day | Q2: Partial Area | R2: Observer Estimate | S2: Corrected Observer Estimate | T2: Date | U2: Stat. Day | V2: Partial Area | W2: Observer Estimate | X2: Corrected Observer Estimate | Y2: Date | Z2: Stat. Day | AA2: Partial Area | AB2: Observer Estimate | AC2: Corrected Observer Estimate | AD2: Date | AE2: Stat. Day | AF2: Partial Area | AG2: Observer Estimate | AH2: Corrected Observer Estimate | AI2: Date | AJ2: Stat. Day | AK2: Partial Area | AL2: Observer Estimate | AM2: Corrected Observer Estimate | AN2: Date | AO2: Stat. Day | AP2: Partial Area | AQ2: Observer Estimate | AR2: Corrected Observer Estimate | AS2: Date | AT2: Stat. Day | AU2: Partial Area
D3: 1982 | E3: =IF(G3/50 = 0, "", G3/50) -> 507.27273 | F3: =IF(MAX(J3,N3,S3,X3,AC3,AH3) = 0, "", MAX(J3,N3,S3,X3,AC3,AH3)) -> 338.18182 | G3: =IF(SUM(V3) = 0, "", SUM(V3)) -> 25363.636 | H3: =IF(E3/F3 = 0, "", E3/F3) -> 1.5 | I3: 0 | J3: =I3/0.55 -> 0 | K3: 29952 | L3: =K3-DATE(YEAR(K3),1,1)+1 -> 1 | M3: 186 | N3: =(M3*1.81818182) -> 338.18182 | O3: 30063 | P3: =O3-DATE(YEAR(O3),1,1)+1 -> 112 | R3: 0 | S3: 0 | T3: 30102 | U3: =T3-DATE(YEAR(T3),1,1)+1 -> 151 | V3: =((N3+I3)/2)*(U3-L3) -> 25363.636
D4: 1983 | E4: =IF(G4/50 = 0, "", G4/50) -> 839.40198 | F4: =IF(MAX(J4,N4,S4,X4,AC4,AH4) = 0, "", MAX(J4,N4,S4,X4,AC4,AH4)) -> 593.43749 | G4: =SUMIF($Q$2:$AU$2, "Partial Area", $Q4:$AU4) -> 41970.099 | H4: =IF(E4/F4 = 0, "", E4/F4) -> 1.4144741 | I4: 0 | J4: =I4/0.55 -> 0 | K4: 30317 | L4: =K4-DATE(YEAR(K4),1,1)+1 -> 1 | M4: 213 | N4: =(M4*1.81818182) -> 387.27273 | O4: 30399 | P4: =O4-DATE(YEAR(O4),1,1)+1 -> 83 | Q4: =((N4+J4)/2)*(P4-L4) -> 15878.182 | R4: 302.5641 | S4: =(R4*1.81818182) -> 550.11655 | T4: 30419 | U4: =T4-DATE(YEAR(T4),1,1)+1 -> 103 | V4: =((S4+N4)/2)*(U4-P4) -> 9373.8928 | W4: 326.39062 | X4: =(W4*1.81818182) -> 593.43749 | Y4: 30428 | Z4: =Y4-DATE(YEAR(Y4),1,1)+1 -> 112 | AA4: =((X4+S4)/2)*(Z4-U4) -> 5145.9932 | AB4: 0 | AC4: =(AB4*1.81818182) -> 0 | AD4: 30467 | AE4: =AD4-DATE(YEAR(AD4),1,1)+1 -> 151 | AF4: =((AC4+X4)/2)*(AE4-Z4) -> 11572.031
D5: 1984 | E5: =IF(G5/50 = 0, "", G5/50) -> 988.31082 | F5: =IF(MAX(J5,N5,S5,X5,AC5,AH5) = 0, "", MAX(J5,N5,S5,X5,AC5,AH5)) -> 646.56687 | G5: =SUMIF($Q$2:$AU$2, "Partial Area", $Q5:$AU5) -> 49415.541 | H5: =IF(E5/F5 = 0, "", E5/F5) -> 1.5285516 | I5: 0 | J5: =I5/0.55 -> 0 | K5: 30682 | L5: =K5-DATE(YEAR(K5),1,1)+1 -> 1 | M5: 298 | N5: =(M5*1.81818182) -> 541.81818 | O5: 30774 | P5: =O5-DATE(YEAR(O5),1,1)+1 -> 93 | Q5: =((N5+J5)/2)*(P5-L5) -> 24923.636 | R5: 355.61178 | S5: =(R5*1.81818182) -> 646.56687 | T5: 30794 | U5: =T5-DATE(YEAR(T5),1,1)+1 -> 113 | V5: =((S5+N5)/2)*(U5-P5) -> 11883.851 | W5: 0 | X5: =(W5*1.81818182) -> 0 | Y5: 30833 | Z5: =Y5-DATE(YEAR(Y5),1,1)+1 -> 152 | AA5: =((X5+S5)/2)*(Z5-U5) -> 12608.054
D6: 1985 | E6: =IF(G6/50 = 0, "", G6/50) -> 1421.6107 | F6: =IF(MAX(J6,N6,S6,X6,AC6,AH6) = 0, "", MAX(J6,N6,S6,X6,AC6,AH6)) -> 942.09421 | G6: =SUMIF($Q$2:$AU$2, "Partial Area", $Q6:$AU6) -> 71080.537 | H6: =IF(E6/F6 = 0, "", E6/F6) -> 1.50899 | I6: 0 | J6: =I6/0.55 -> 0 | K6: 31048 | L6: =K6-DATE(YEAR(K6),1,1)+1 -> 1 | M6: 471 | N6: =(M6*1.81818182) -> 856.36364 | O6: 31148 | P6: =O6-DATE(YEAR(O6),1,1)+1 -> 101 | Q6: =((N6+J6)/2)*(P6-L6) -> 42818.182 | R6: 518.15181 | S6: =(R6*1.81818182) -> 942.09421 | T6: 31159 | U6: =T6-DATE(YEAR(T6),1,1)+1 -> 112 | V6: =((S6+N6)/2)*(U6-P6) -> 9891.5182 | W6: 0 | X6: =(W6*1.81818182) -> 0 | Y6: 31198 | Z6: =Y6-DATE(YEAR(Y6),1,1)+1 -> 151 | AA6: =((X6+S6)/2)*(Z6-U6) -> 18370.837
D7: 1986 | E7: =IF(G7/50 = 0, "", G7/50) -> 601.60452 | F7: =IF(MAX(J7,N7,S7,X7,AC7,AH7) = 0, "", MAX(J7,N7,S7,X7,AC7,AH7)) -> 398.34969 | G7: =SUMIF($Q$2:$AU$2, "Partial Area", $Q7:$AU7) -> 30080.226 | H7: =IF(E7/F7 = 0, "", E7/F7) -> 1.5102422 | I7: 0 | J7: =I7/0.55 -> 0 | K7: 31413 | L7: =K7-DATE(YEAR(K7),1,1)+1 -> 1 | M7: 79 | N7: =(M7*1.81818182) -> 143.63636 | O7: 31452 | P7: =O7-DATE(YEAR(O7),1,1)+1 -> 40 | Q7: =((N7+J7)/2)*(P7-L7) -> 2800.9091 | R7: 219.09233 | S7: =(R7*1.81818182) -> 398.34969 | T7: 31524 | U7: =T7-DATE(YEAR(T7),1,1)+1 -> 112 | V7: =((S7+N7)/2)*(U7-P7) -> 19511.498 | W7: 0 | X7: =(W7*1.81818182) -> 0 | Y7: 31563 | Z7: =Y7-DATE(YEAR(Y7),1,1)+1 -> 151 | AA7: =((X7+S7)/2)*(Z7-U7) -> 7767.819
D8: 1987 | E8: =IF(G8/50 = 0, "", G8/50) -> 1193.7008 | F8: =IF(MAX(J8,N8,S8,X8,AC8,AH8) = 0, "", MAX(J8,N8,S8,X8,AC8,AH8)) -> 818.05711 | G8: =SUMIF($Q$2:$AU$2, "Partial Area", $Q8:$AU8) -> 59685.038 | H8: =IF(E8/F8 = 0, "", E8/F8) -> 1.45919 | I8: 0 | J8: =I8/0.55 -> 0 | K8: 31778 | L8: =K8-DATE(YEAR(K8),1,1)+1 -> 1 | M8: 328 | N8: =(M8*1.81818182) -> 596.36364 | O8: 31863 | P8: =O8-DATE(YEAR(O8),1,1)+1 -> 86 | Q8: =((N8+J8)/2)*(P8-L8) -> 25345.455 | R8: 449.93141 | S8: =(R8*1.81818182) -> 818.05711 | T8: 31889 | U8: =T8-DATE(YEAR(T8),1,1)+1 -> 112 | V8: =((S8+N8)/2)*(U8-P8) -> 18387.47 | W8: 0 | X8: =(W8*1.81818182) -> 0 | Y8: 31928 | Z8: =Y8-DATE(YEAR(Y8),1,1)+1 -> 151 | AA8: =((X8+S8)/2)*(Z8-U8) -> 15952.114
D9: 1988 | E9: =IF(G9/50 = 0, "", G9/50) -> 1399.7982 | F9: =IF(MAX(J9,N9,S9,X9,AC9,AH9) = 0, "", MAX(J9,N9,S9,X9,AC9,AH9)) -> 920.86033 | G9: =SUMIF($Q$2:$AU$2, "Partial Area", $Q9:$AU9) -> 69989.908 | H9: =IF(E9/F9 = 0, "", E9/F9) -> 1.5200982 | I9: 0 | J9: =I9/0.55 -> 0 | K9: 32143 | L9: =K9-DATE(YEAR(K9),1,1)+1 -> 1 | M9: 251 | N9: =(M9*1.81818182) -> 456.36364 | O9: 32197 | P9: =O9-DATE(YEAR(O9),1,1)+1 -> 55 | Q9: =((N9+J9)/2)*(P9-L9) -> 12321.818 | R9: 506.47318 | S9: =(R9*1.81818182) -> 920.86033 | T9: 31524 | U9: =T9-DATE(YEAR(T9),1,1)+1 -> 112 | V9: =((S9+N9)/2)*(U9-P9) -> 39250.883 | W9: 0 | X9: =(W9*1.81818182) -> 0 | Y9: 32294 | Z9: =Y9-DATE(YEAR(Y9),1,1)+1 -> 152 | AA9: =((X9+S9)/2)*(Z9-U9) -> 18417.207
D10: 1989 | E10: =IF(G10/50 = 0, "", G10/50) -> 278.233 | F10: =IF(MAX(J10,N10,S10,X10,AC10,AH10) = 0, "", MAX(J10,N10,S10,X10,AC10,AH10)) -> 148.14815 | G10: =SUMIF($Q$2:$AU$2, "Partial Area", $Q10:$AU10) -> 13911.65 | H10: =IF(E10/F10 = 0, "", E10/F10) -> 1.8780727 | I10: 0 | J10: =I10/0.55 -> 0 | K10: 32509 | L10: =K10-DATE(YEAR(K10),1,1)+1 -> 1 | M10: 80 | N10: =(M10*1.81818182) -> 145.45455 | O10: 32548 | P10: =O10-DATE(YEAR(O10),1,1)+1 -> 40 | Q10: =((N10+J10)/2)*(P10-L10) -> 2836.3636 | R10: 44 | S10: =(R10*1.81818182) -> 80 | T10: 32568 | U10: =T10-DATE(YEAR(T10),1,1)+1 -> 60 | V10: =((S10+N10)/2)*(U10-P10) -> 2254.5455 | W10: 81.481481 | X10: =(W10*1.81818182) -> 148.14815 | Y10: 32620 | Z10: =Y10-DATE(YEAR(Y10),1,1)+1 -> 112 | AA10: =((X10+S10)/2)*(Z10-U10) -> 5931.8519 | AB10: 0 | AC10: =(AB10*1.81818182) -> 0 | AD10: 32659 | AE10: =AD10-DATE(YEAR(AD10),1,1)+1 -> 151 | AF10: =((AC10+X10)/2)*(AE10-Z10) -> 2888.8889
D11: 1990 | E11: =IF(G11/50 = 0, "", G11/50) -> 536.71111 | F11: =IF(MAX(J11,N11,S11,X11,AC11,AH11) = 0, "", MAX(J11,N11,S11,X11,AC11,AH11)) -> 355.55556 | G11: =SUMIF($Q$2:$AU$2, "Partial Area", $Q11:$AU11) -> 26835.556 | H11: =IF(E11/F11 = 0, "", E11/F11) -> 1.5095 | I11: 0 | J11: =I11/0.55 -> 0 | K11: 32874 | L11: =K11-DATE(YEAR(K11),1,1)+1 -> 1 | M11: 88 | N11: =(M11*1.81818182) -> 160 | O11: 32923 | P11: =O11-DATE(YEAR(O11),1,1)+1 -> 50 | Q11: =((N11+J11)/2)*(P11-L11) -> 3920 | R11: 195.55556 | S11: =(R11*1.81818182) -> 355.55556 | T11: 32985 | U11: =T11-DATE(YEAR(T11),1,1)+1 -> 112 | V11: =((S11+N11)/2)*(U11-P11) -> 15982.222 | W11: 0 | X11: =(W11*1.81818182) -> 0 | Y11: 33024 | Z11: =Y11-DATE(YEAR(Y11),1,1)+1 -> 151 | AA11: =((X11+S11)/2)*(Z11-U11) -> 6933.3333
D12: 1991 | E12: =IF(G12/50 = 0, "", G12/50) -> 238.57181 | F12: =IF(MAX(J12,N12,S12,X12,AC12,AH12) = 0, "", MAX(J12,N12,S12,X12,AC12,AH12)) -> 147.53692 | G12: =SUMIF($Q$2:$AU$2, "Partial Area", $Q12:$AU12) -> 11928.59 | H12: =IF(E12/F12 = 0, "", E12/F12) -> 1.6170312 | I12: 0 | J12: =I12/0.55 -> 0 | K12: 33239 | L12: =K12-DATE(YEAR(K12),1,1)+1 -> 1 | M12: 34 | N12: =(M12*1.81818182) -> 61.818182 | O12: 33267 | P12: =O12-DATE(YEAR(O12),1,1)+1 -> 29 | Q12: =((N12+J12)/2)*(P12-L12) -> 865.45455 | R12: 59.15493 | S12: =(R12*1.81818182) -> 107.55442 | T12: 33323 | U12: =T12-DATE(YEAR(T12),1,1)+1 -> 85 | V12: =((S12+N12)/2)*(U12-P12) -> 4742.4328 | W12: 81.145308 | X12: =(W12*1.81818182) -> 147.53692 | Y12: 33350 | Z12: =Y12-DATE(YEAR(Y12),1,1)+1 -> 112 | AA12: =((X12+S12)/2)*(Z12-U12) -> 3443.7331 | AB12: 0 | AC12: =(AB12*1.81818182) -> 0 | AD12: 33389 | AE12: =AD12-DATE(YEAR(AD12),1,1)+1 -> 151 | AF12: =((AC12+X12)/2)*(AE12-Z12) -> 2876.97
D13: 1992 | E13: =IF(G13/50 = 0, "", G13/50) -> 507.68161 | F13: =IF(MAX(J13,N13,S13,X13,AC13,AH13) = 0, "", MAX(J13,N13,S13,X13,AC13,AH13)) -> 332.626 | G13: =SUMIF($Q$2:$AU$2, "Partial Area", $Q13:$AU13) -> 25384.08 | H13: =IF(E13/F13 = 0, "", E13/F13) -> 1.5262836 | I13: 0 | J13: =I13/0.55 -> 0 | K13: 33604 | L13: =K13-DATE(YEAR(K13),1,1)+1 -> 1 | M13: 117 | N13: =(M13*1.81818182) -> 212.72727 | O13: 33674 | P13: =O13-DATE(YEAR(O13),1,1)+1 -> 71 | Q13: =((N13+J13)/2)*(P13-L13) -> 7445.4546 | R13: 182.9443 | S13: =(R13*1.81818182) -> 332.626 | T13: 33716 | U13: =T13-DATE(YEAR(T13),1,1)+1 -> 113 | V13: =((S13+N13)/2)*(U13-P13) -> 11452.419 | W13: 0 | X13: =(W13*1.81818182) -> 0 | Y13: 33755 | Z13: =Y13-DATE(YEAR(Y13),1,1)+1 -> 152 | AA13: =((X13+S13)/2)*(Z13-U13) -> 6486.207
D14: 1993 | E14: =IF(G14/50 = 0, "", G14/50) -> 224.58972 | F14: =IF(MAX(J14,N14,S14,X14,AC14,AH14) = 0, "", MAX(J14,N14,S14,X14,AC14,AH14)) -> 183.63636 | G14: =SUMIF($Q$2:$AU$2, "Partial Area", $Q14:$AU14) -> 11229.486 | H14: =IF(E14/F14 = 0, "", E14/F14) -> 1.2230133 | I14: 0 | J14: =I14/0.55 -> 0 | K14: 33970 | L14: =K14-DATE(YEAR(K14),1,1)+1 -> 1 | M14: 101 | N14: =(M14*1.81818182) -> 183.63636 | O14: 34025 | P14: =O14-DATE(YEAR(O14),1,1)+1 -> 56 | Q14: =((N14+J14)/2)*(P14-L14) -> 5050 | R14: 14.141414 | S14: =(R14*1.81818182) -> 25.711662 | T14: 34079 | U14: =T14-DATE(YEAR(T14),1,1)+1 -> 110 | V14: =((S14+N14)/2)*(U14-P14) -> 5652.3967 | W14: 0 | X14: =(W14*1.81818182) -> 0 | Y14: 34120 | Z14: =Y14-DATE(YEAR(Y14),1,1)+1 -> 151 | AA14: =((X14+S14)/2)*(Z14-U14) -> 527.08907
D15: 1994 | E15: =IF(G15/50 = 0, "", G15/50) -> 86.655453 | F15: =IF(MAX(J15,N15,S15,X15,AC15,AH15) = 0, "", MAX(J15,N15,S15,X15,AC15,AH15)) -> 59.717326 | G15: =SUMIF($Q$2:$AU$2, "Partial Area", $Q15:$AU15) -> 4332.7726 | H15: =IF(E15/F15 = 0, "", E15/F15) -> 1.451094 | I15: 0 | J15: =I15/0.55 -> 0 | K15: 34335 | L15: =K15-DATE(YEAR(K15),1,1)+1 -> 1 | M15: 24 | N15: =(M15*1.81818182) -> 43.636364 | O15: 34421 | P15: =O15-DATE(YEAR(O15),1,1)+1 -> 87 | Q15: =((N15+J15)/2)*(P15-L15) -> 1876.3636 | R15: 32.844529 | S15: =(R15*1.81818182) -> 59.717326 | T15: 34446 | U15: =T15-DATE(YEAR(T15),1,1)+1 -> 112 | V15: =((S15+N15)/2)*(U15-P15) -> 1291.9211 | W15: 0 | X15: =(W15*1.81818182) -> 0 | Y15: 34485 | Z15: =Y15-DATE(YEAR(Y15),1,1)+1 -> 151 | AA15: =((X15+S15)/2)*(Z15-U15) -> 1164.4879
D16: 1995 | E16: =IF(G16/50 = 0, "", G16/50) -> 258.28365 | F16: =IF(MAX(J16,N16,S16,X16,AC16,AH16) = 0, "", MAX(J16,N16,S16,X16,AC16,AH16)) -> 170.7213 | G16: =SUMIF($Q$2:$AU$2, "Partial Area", $Q16:$AU16) -> 12914.183 | H16: =IF(E16/F16 = 0, "", E16/F16) -> 1.5128965 | I16: 0 | J16: =I16/0.55 -> 0 | K16: 34700 | L16: =K16-DATE(YEAR(K16),1,1)+1 -> 1 | M16: 51 | N16: =(M16*1.81818182) -> 92.727273 | O16: 34759 | P16: =O16-DATE(YEAR(O16),1,1)+1 -> 60 | Q16: =((N16+J16)/2)*(P16-L16) -> 2735.4545 | R16: 93.896714 | S16: =(R16*1.81818182) -> 170.7213 | T16: 34811 | U16: =T16-DATE(YEAR(T16),1,1)+1 -> 112 | V16: =((S16+N16)/2)*(U16-P16) -> 6849.6628 | W16: 0 | X16: =(W16*1.81818182) -> 0 | Y16: 34850 | Z16: =Y16-DATE(YEAR(Y16),1,1)+1 -> 151 | AA16: =((X16+S16)/2)*(Z16-U16) -> 3329.0653
D17: 1996 | E17: =IF(G17/50 = 0, "", G17/50) -> 152.97272 | F17: =IF(MAX(J17,N17,S17,X17,AC17,AH17) = 0, "", MAX(J17,N17,S17,X17,AC17,AH17)) -> 105.38352 | G17: =SUMIF($Q$2:$AU$2, "Partial Area", $Q17:$AU17) -> 7648.6362 | H17: =IF(E17/F17 = 0, "", E17/F17) -> 1.4515811 | I17: 0 | J17: =I17/0.55 -> 0 | K17: 35065 | L17: =K17-DATE(YEAR(K17),1,1)+1 -> 1 | M17: 42 | N17: =(M17*1.81818182) -> 76.363636 | O17: 35152 | P17: =O17-DATE(YEAR(O17),1,1)+1 -> 88 | Q17: =((N17+J17)/2)*(P17-L17) -> 3321.8182 | R17: 57.960934 | S17: =(R17*1.81818182) -> 105.38352 | T17: 35177 | U17: =T17-DATE(YEAR(T17),1,1)+1 -> 113 | V17: =((S17+N17)/2)*(U17-P17) -> 2271.8394 | W17: 0 | X17: =(W17*1.81818182) -> 0 | Y17: 35216 | Z17: =Y17-DATE(YEAR(Y17),1,1)+1 -> 152 | AA17: =((X17+S17)/2)*(Z17-U17) -> 2054.9786
D18: 1998 | E18: =IF(G18/50 = 0, "", G18/50) -> 25.988765 | F18: =IF(MAX(J18,N18,S18,X18,AC18,AH18) = 0, "", MAX(J18,N18,S18,X18,AC18,AH18)) -> 18.065746 | G18: =SUMIF($Q$2:$AU$2, "Partial Area", $Q18:$AU18) -> 1299.4383 | H18: =IF(E18/F18 = 0, "", E18/F18) -> 1.4385659 | I18: 0 | J18: =I18/0.55 -> 0 | K18: 35796 | L18: =K18-DATE(YEAR(K18),1,1)+1 -> 1 | M18: 5 | N18: =(M18*1.81818182) -> 9.0909091 | O18: 35858 | P18: =O18-DATE(YEAR(O18),1,1)+1 -> 63 | Q18: =((N18+J18)/2)*(P18-L18) -> 281.81818 | R18: 9.9361602 | S18: =(R18*1.81818182) -> 18.065746 | T18: 35907 | U18: =T18-DATE(YEAR(T18),1,1)+1 -> 112 | V18: =((S18+N18)/2)*(U18-P18) -> 665.33804 | W18: 0 | X18: =(W18*1.81818182) -> 0 | Y18: 35946 | Z18: =Y18-DATE(YEAR(Y18),1,1)+1 -> 151 | AA18: =((X18+S18)/2)*(Z18-U18) -> 352.28204
D19: 1999 | E19: =IF(G19/50 = 0, "", G19/50) -> 265.06964 | F19: =IF(MAX(J19,N19,S19,X19,AC19,AH19) = 0, "", MAX(J19,N19,S19,X19,AC19,AH19)) -> 212.65284 | G19: =SUMIF($Q$2:$AU$2, "Partial Area", $Q19:$AU19) -> 13253.482 | H19: =IF(E19/F19 = 0, "", E19/F19) -> 1.24649 | I19: 0 | J19: =I19/0.55 -> 0 | K19: 36161 | L19: =K19-DATE(YEAR(K19),1,1)+1 -> 1 | M19: 40 | N19: =(M19*1.81818182) -> 72.727273 | O19: 36227 | P19: =O19-DATE(YEAR(O19),1,1)+1 -> 67 | Q19: =((N19+J19)/2)*(P19-L19) -> 2400 | R19: 100 | S19: =(R19*1.81818182) -> 181.81818 | T19: 36258 | U19: =T19-DATE(YEAR(T19),1,1)+1 -> 98 | V19: =((S19+N19)/2)*(U19-P19) -> 3945.4545 | W19: 116.95906 | X19: =(W19*1.81818182) -> 212.65284 | Y19: 36272 | Z19: =Y19-DATE(YEAR(Y19),1,1)+1 -> 112 | AA19: =((X19+S19)/2)*(Z19-U19) -> 2761.2972 | AB19: 0 | AC19: =(AB19*1.81818182) -> 0 | AD19: 36311 | AE19: =AD19-DATE(YEAR(AD19),1,1)+1 -> 151 | AF19: =((AC19+X19)/2)*(AE19-Z19) -> 4146.7305
D20: 2000 | E20: =IF(G20/50 = 0, "", G20/50) -> 49.51579 | F20: =IF(MAX(J20,N20,S20,X20,AC20,AH20) = 0, "", MAX(J20,N20,S20,X20,AC20,AH20)) -> 32.822967 | G20: =SUMIF($Q$2:$AU$2, "Partial Area", $Q20:$AU20) -> 2475.7895 | H20: =IF(E20/F20 = 0, "", E20/F20) -> 1.5085714 | I20: 0 | J20: =I20/0.55 -> 0 | K20: 36526 | L20: =K20-DATE(YEAR(K20),1,1)+1 -> 1 | M20: 14 | N20: =(M20*1.81818182) -> 25.454545 | O20: 36613 | P20: =O20-DATE(YEAR(O20),1,1)+1 -> 88 | Q20: =((N20+J20)/2)*(P20-L20) -> 1107.2727 | R20: 18.052632 | S20: =(R20*1.81818182) -> 32.822967 | T20: 36638 | U20: =T20-DATE(YEAR(T20),1,1)+1 -> 113 | V20: =((S20+N20)/2)*(U20-P20) -> 728.4689 | W20: 0 | X20: =(W20*1.81818182) -> 0 | Y20: 36677 | Z20: =Y20-DATE(YEAR(Y20),1,1)+1 -> 152 | AA20: =((X20+S20)/2)*(Z20-U20) -> 640.04785 | AE20: =AD20-DATE(YEAR(AD20),1,1)+1 -> 0
D21: 2001 | E21: =IF(G21/50 = 0, "", G21/50) -> 233.7681 | F21: =IF(MAX(J21,N21,S21,X21,AC21,AH21) = 0, "", MAX(J21,N21,S21,X21,AC21,AH21)) -> 138.18182 | G21: =SUMIF($Q$2:$AU$2, "Partial Area", $Q21:$AU21) -> 11688.405 | H21: =IF(E21/F21 = 0, "", E21/F21) -> 1.6917429 | I21: 0 | J21: =I21/0.55 -> 0 | K21: 36892 | L21: =K21-DATE(YEAR(K21),1,1)+1 -> 1 | M21: 76 | N21: =(M21*1.81818182) -> 138.18182 | O21: 36962 | P21: =O21-DATE(YEAR(O21),1,1)+1 -> 71 | Q21: =((N21+J21)/2)*(P21-L21) -> 4836.3636 | R21: 53.521127 | S21: =(R21*1.81818182) -> 97.31114 | T21: 36987 | U21: =T21-DATE(YEAR(T21),1,1)+1 -> 96 | V21: =((S21+N21)/2)*(U21-P21) -> 2943.662 | W21: 62.597809 | X21: =(W21*1.81818182) -> 113.8142 | Y21: 37003 | Z21: =Y21-DATE(YEAR(Y21),1,1)+1 -> 112 | AA21: =((X21+S21)/2)*(Z21-U21) -> 1689.0027 | AB21: 0 | AC21: =(AB21*1.81818182) -> 0 | AD21: 37042 | AE21: =AD21-DATE(YEAR(AD21),1,1)+1 -> 151 | AF21: =((AC21+X21)/2)*(AE21-Z21) -> 2219.3769
D22: 2002 | E22: =IF(G22/50 = 0, "", G22/50) -> 191.21818 | F22: =IF(MAX(J22,N22,S22,X22,AC22,AH22) = 0, "", MAX(J22,N22,S22,X22,AC22,AH22)) -> 132.72727 | G22: =SUMIF($Q$2:$AU$2, "Partial Area", $Q22:$AU22) -> 9560.9091 | H22: =IF(E22/F22 = 0, "", E22/F22) -> 1.4406849 | I22: 0 | J22: =I22/0.55 -> 0 | K22: 37257 | L22: =K22-DATE(YEAR(K22),1,1)+1 -> 1 | M22: 17 | N22: =(M22*1.81818182) -> 30.909091 | O22: 37274 | P22: =O22-DATE(YEAR(O22),1,1)+1 -> 18 | Q22: =((N22+J22)/2)*(P22-L22) -> 262.72727 | R22: 16 | S22: =(R22*1.81818182) -> 29.090909 | T22: 37300 | U22: =T22-DATE(YEAR(T22),1,1)+1 -> 44 | V22: =((S22+N22)/2)*(U22-P22) -> 780 | W22: 46 | X22: =(W22*1.81818182) -> 83.636364 | Y22: 37324 | Z22: =Y22-DATE(YEAR(Y22),1,1)+1 -> 68 | AA22: =((X22+S22)/2)*(Z22-U22) -> 1352.7273 | AB22: 50 | AC22: =(AB22*1.81818182) -> 90.909091 | AD22: 37337 | AE22: =AD22-DATE(YEAR(AD22),1,1)+1 -> 81 | AF22: =((AC22+X22)/2)*(AE22-Z22) -> 1134.5455 | AG22: 73 | AH22: =(AG22*1.81818182) -> 132.72727 | AI22: 37372 | AJ22: =AI22-DATE(YEAR(AI22),1,1)+1 -> 116 | AK22: =((AH22+AC22)/2)*(AJ22-AE22) -> 3913.6364 | AL22: 29 | AM22: =(AL22*1.81818182) -> 52.727273 | AN22: 37390 | AO22: =AN22-DATE(YEAR(AN22),1,1)+1 -> 134 | AP22: =((AM22+AH22)/2)*(AO22-AJ22) -> 1669.0909 | AQ22: 0 | AR22: =(AQ22*1.81818182) -> 0 | AS22: 37407 | AT22: =AS22-DATE(YEAR(AS22),1,1)+1 -> 151 | AU22: =((AR22+AM22)/2)*(AT22-AO22) -> 448.18182
D23: 2003 | E23: =IF(G23/50 = 0, "", G23/50) -> 127.09091 | F23: =IF(MAX(J23,N23,S23,X23,AC23,AH23) = 0, "", MAX(J23,N23,S23,X23,AC23,AH23)) -> 90.909091 | G23: =SUMIF($Q$2:$AU$2, "Partial Area", $Q23:$AU23) -> 6354.5455 | H23: =IF(E23/F23 = 0, "", E23/F23) -> 1.398 | I23: 0 | J23: =I23/0.55 -> 0 | K23: 37622 | L23: =K23-DATE(YEAR(K23),1,1)+1 -> 1 | M23: 5 | N23: =(M23*1.81818182) -> 9.0909091 | O23: 37641 | P23: =O23-DATE(YEAR(O23),1,1)+1 -> 20 | Q23: =((N23+J23)/2)*(P23-L23) -> 86.363636 | R23: 19 | S23: =(R23*1.81818182) -> 34.545455 | T23: 37664 | U23: =T23-DATE(YEAR(T23),1,1)+1 -> 43 | V23: =((S23+N23)/2)*(U23-P23) -> 501.81818 | W23: 21 | X23: =(W23*1.81818182) -> 38.181818 | Y23: 37687 | Z23: =Y23-DATE(YEAR(Y23),1,1)+1 -> 66 | AA23: =((X23+S23)/2)*(Z23-U23) -> 836.36364 | AB23: 46 | AC23: =(AB23*1.81818182) -> 83.636364 | AD23: 37718 | AE23: =AD23-DATE(YEAR(AD23),1,1)+1 -> 97 | AF23: =((AC23+X23)/2)*(AE23-Z23) -> 1888.1818 | AG23: 50 | AH23: =(AG23*1.81818182) -> 90.909091 | AI23: 37734 | AJ23: =AI23-DATE(YEAR(AI23),1,1)+1 -> 113 | AK23: =((AH23+AC23)/2)*(AJ23-AE23) -> 1396.3636 | AL23: 20 | AM23: =(AL23*1.81818182) -> 36.363636 | AN23: 37755 | AO23: =AN23-DATE(YEAR(AN23),1,1)+1 -> 134 | AP23: =((AM23+AH23)/2)*(AO23-AJ23) -> 1336.3636 | AQ23: 0 | AR23: =(AQ23*1.81818182) -> 0 | AS23: 37772 | AT23: =AS23-DATE(YEAR(AS23),1,1)+1 -> 151 | AU23: =((AR23+AM23)/2)*(AT23-AO23) -> 309.09091
D24: 2004 | E24: =IF(G24/50 = 0, "", G24/50) -> 111.12727 | F24: =IF(MAX(J24,N24,S24,X24,AC24,AH24) = 0, "", MAX(J24,N24,S24,X24,AC24,AH24)) -> 81.818182 | G24: =SUMIF($Q$2:$AU$2, "Partial Area", $Q24:$AU24) -> 5556.3636 | H24: =IF(E24/F24 = 0, "", E24/F24) -> 1.3582222 | I24: 0 | J24: =I24/0.55 -> 0 | K24: 37987 | L24: =K24-DATE(YEAR(K24),1,1)+1 -> 1 | M24: 6 | N24: =(M24*1.81818182) -> 10.909091 | O24: 38022 | P24: =O24-DATE(YEAR(O24),1,1)+1 -> 36 | Q24: =((N24+J24)/2)*(P24-L24) -> 190.90909 | R24: 21 | S24: =(R24*1.81818182) -> 38.181818 | T24: 38048 | U24: =T24-DATE(YEAR(T24),1,1)+1 -> 62 | V24: =((S24+N24)/2)*(U24-P24) -> 638.18182 | W24: 24 | X24: =(W24*1.81818182) -> 43.636364 | Y24: 38069 | Z24: =Y24-DATE(YEAR(Y24),1,1)+1 -> 83 | AA24: =((X24+S24)/2)*(Z24-U24) -> 859.09091 | AB24: 45 | AC24: =(AB24*1.81818182) -> 81.818182 | AD24: 38091 | AE24: =AD24-DATE(YEAR(AD24),1,1)+1 -> 105 | AF24: =((AC24+X24)/2)*(AE24-Z24) -> 1380 | AG24: 41 | AH24: =(AG24*1.81818182) -> 74.545455 | AI24: 38106 | AJ24: =AI24-DATE(YEAR(AI24),1,1)+1 -> 120 | AK24: =((AH24+AC24)/2)*(AJ24-AE24) -> 1172.7273 | AL24: 26 | AM24: =(AL24*1.81818182) -> 47.272727 | AN24: 38121 | AO24: =AN24-DATE(YEAR(AN24),1,1)+1 -> 135 | AP24: =((AM24+AH24)/2)*(AO24-AJ24) -> 913.63636 | AQ24: 0 | AR24: =(AQ24*1.81818182) -> 0 | AS24: 38138 | AT24: =AS24-DATE(YEAR(AS24),1,1)+1 -> 152 | AU24: =((AR24+AM24)/2)*(AT24-AO24) -> 401.81818
D25: 2005 | E25: =IF(G25/50 = 0, "", G25/50) -> 144.43636 | F25: =IF(MAX(J25,N25,S25,X25,AC25,AH25) = 0, "", MAX(J25,N25,S25,X25,AC25,AH25)) -> 110.90909 | G25: =SUMIF($Q$2:$AU$2, "Partial Area", $Q25:$AU25) -> 7221.8182 | H25: =IF(E25/F25 = 0, "", E25/F25) -> 1.3022951 | I25: 0 | J25: =I25/0.55 -> 0 | K25: 38353 | L25: =K25-DATE(YEAR(K25),1,1)+1 -> 1 | M25: 9 | N25: =(M25*1.81818182) -> 16.363636 | O25: 38394 | P25: =O25-DATE(YEAR(O25),1,1)+1 -> 42 | Q25: =((N25+J25)/2)*(P25-L25) -> 335.45455 | R25: 32 | S25: =(R25*1.81818182) -> 58.181818 | T25: 38419 | U25: =T25-DATE(YEAR(T25),1,1)+1 -> 67 | V25: =((S25+N25)/2)*(U25-P25) -> 931.81818 | W25: 61 | X25: =(W25*1.81818182) -> 110.90909 | Y25: 38457 | Z25: =Y25-DATE(YEAR(Y25),1,1)+1 -> 105 | AA25: =((X25+S25)/2)*(Z25-U25) -> 3212.7273 | AB25: 47 | AC25: =(AB25*1.81818182) -> 85.454546 | AD25: 38471 | AE25: =AD25-DATE(YEAR(AD25),1,1)+1 -> 119 | AF25: =((AC25+X25)/2)*(AE25-Z25) -> 1374.5455 | AG25: 0 | AH25: =(AG25*1.81818182) -> 0 | AI25: 38503 | AJ25: =AI25-DATE(YEAR(AI25),1,1)+1 -> 151 | AK25: =((AH25+AC25)/2)*(AJ25-AE25) -> 1367.2727 | AR25: =(AQ25*1.81818182) -> 0 | AT25: =AS25-DATE(YEAR(AS25),1,1)+1 -> 0
D26: 2006 | E26: =IF(G26/50 = 0, "", G26/50) -> 211.94545 | F26: =IF(MAX(J26,N26,S26,X26,AC26,AH26) = 0, "", MAX(J26,N26,S26,X26,AC26,AH26)) -> 112.72727 | G26: =SUMIF($Q$2:$AU$2, "Partial Area", $Q26:$AU26) -> 10597.273 | H26: =IF(E26/F26 = 0, "", E26/F26) -> 1.8801613 | I26: 0 | J26: =I26/0.55 -> 0 | K26: 38718 | L26: =K26-DATE(YEAR(K26),1,1)+1 -> 1 | M26: 32 | N26: =(M26*1.81818182) -> 58.181818 | O26: 38763 | P26: =O26-DATE(YEAR(O26),1,1)+1 -> 46 | Q26: =((N26+J26)/2)*(P26-L26) -> 1309.0909 | R26: 59 | S26: =(R26*1.81818182) -> 107.27273 | T26: 38797 | U26: =T26-DATE(YEAR(T26),1,1)+1 -> 80 | V26: =((S26+N26)/2)*(U26-P26) -> 2812.7273 | W26: 62 | X26: =(W26*1.81818182) -> 112.72727 | Y26: 38820 | Z26: =Y26-DATE(YEAR(Y26),1,1)+1 -> 103 | AA26: =((X26+S26)/2)*(Z26-U26) -> 2530 | AB26: 62 | AC26: =(AB26*1.81818182) -> 112.72727 | AD26: 38842 | AE26: =AD26-DATE(YEAR(AD26),1,1)+1 -> 125 | AF26: =((AC26+X26)/2)*(AE26-Z26) -> 2480 | AG26: 0 | AH26: =(AG26*1.81818182) -> 0 | AI26: 38868 | AJ26: =AI26-DATE(YEAR(AI26),1,1)+1 -> 151 | AK26: =((AH26+AC26)/2)*(AJ26-AE26) -> 1465.4545 | AR26: =(AQ26*1.81818182) -> 0 | AT26: =AS26-DATE(YEAR(AS26),1,1)+1 -> 0
D27: 2007 | E27: =IF(G27/50 = 0, "", G27/50) -> 148.10909 | F27: =IF(MAX(J27,N27,S27,X27,AC27,AH27) = 0, "", MAX(J27,N27,S27,X27,AC27,AH27)) -> 109.09091 | G27: =SUMIF($Q$2:$AU$2, "Partial Area", $Q27:$AU27) -> 7405.4546 | H27: =IF(E27/F27 = 0, "", E27/F27) -> 1.3576667 | I27: 0 | J27: =I27/0.55 -> 0 | K27: 39083 | L27: =K27-DATE(YEAR(K27),1,1)+1 -> 1 | M27: 18 | N27: =(M27*1.81818182) -> 32.727273 | O27: 39136 | P27: =O27-DATE(YEAR(O27),1,1)+1 -> 54 | Q27: =((N27+J27)/2)*(P27-L27) -> 867.27273 | R27: 50 | S27: =(R27*1.81818182) -> 90.909091 | T27: 39170 | U27: =T27-DATE(YEAR(T27),1,1)+1 -> 88 | V27: =((S27+N27)/2)*(U27-P27) -> 2101.8182 | W27: 60 | X27: =(W27*1.81818182) -> 109.09091 | Y27: 39192 | Z27: =Y27-DATE(YEAR(Y27),1,1)+1 -> 110 | AA27: =((X27+S27)/2)*(Z27-U27) -> 2200 | AB27: 0 | AC27: =(AB27*1.81818182) -> 0 | AD27: 39233 | AE27: =AD27-DATE(YEAR(AD27),1,1)+1 -> 151 | AF27: =((AC27+X27)/2)*(AE27-Z27) -> 2236.3636 | AR27: =(AQ27*1.81818182) -> 0 | AT27: =AS27-DATE(YEAR(AS27),1,1)+1 -> 0
D28: 2008 | E28: =IF(G28/50 = 0, "", G28/50) -> 60.981818 | F28: =IF(MAX(J28,N28,S28,X28,AC28,AH28) = 0, "", MAX(J28,N28,S28,X28,AC28,AH28)) -> 32.727273 | G28: =SUMIF($Q$2:$AU$2, "Partial Area", $Q28:$AU28) -> 3049.0909 | H28: =IF(E28/F28 = 0, "", E28/F28) -> 1.8633333 | I28: 0 | J28: =I28/0.55 -> 0 | K28: 39448 | L28: =K28-DATE(YEAR(K28),1,1)+1 -> 1 | M28: 18 | N28: =(M28*1.81818182) -> 32.727273 | O28: 39515 | P28: =O28-DATE(YEAR(O28),1,1)+1 -> 68 | Q28: =((N28+J28)/2)*(P28-L28) -> 1096.3636 | R28: 17 | S28: =(R28*1.81818182) -> 30.909091 | T28: 39555 | U28: =T28-DATE(YEAR(T28),1,1)+1 -> 108 | V28: =((S28+N28)/2)*(U28-P28) -> 1272.7273 | W28: 0 | X28: =(W28*1.81818182) -> 0 | Y28: 39599 | Z28: =Y28-DATE(YEAR(Y28),1,1)+1 -> 152 | AA28: =((X28+S28)/2)*(Z28-U28) -> 680 | AR28: =(AQ28*1.81818182) -> 0 | AT28: =AS28-DATE(YEAR(AS28),1,1)+1 -> 0
D29: 2009 | E29: =IF(G29/50 = 0, "", G29/50) -> 96.218182 | F29: =IF(MAX(J29,N29,S29,X29,AC29,AH29) = 0, "", MAX(J29,N29,S29,X29,AC29,AH29)) -> 69.090909 | G29: =SUMIF($Q$2:$AU$2, "Partial Area", $Q29:$AU29) -> 4810.9091 | H29: =IF(E29/F29 = 0, "", E29/F29) -> 1.3926316 | I29: 0 | J29: =I29/0.55 -> 0 | K29: 39814 | L29: =K29-DATE(YEAR(K29),1,1)+1 -> 1 | M29: 24 | N29: =(M29*1.81818182) -> 43.636364 | O29: 39898 | P29: =O29-DATE(YEAR(O29),1,1)+1 -> 85 | Q29: =((N29+J29)/2)*(P29-L29) -> 1832.7273 | R29: 38 | S29: =(R29*1.81818182) -> 69.090909 | T29: 39930 | U29: =T29-DATE(YEAR(T29),1,1)+1 -> 117 | V29: =((S29+N29)/2)*(U29-P29) -> 1803.6364 | W29: 0 | X29: =(W29*1.81818182) -> 0 | Y29: 39964 | Z29: =Y29-DATE(YEAR(Y29),1,1)+1 -> 151 | AA29: =((X29+S29)/2)*(Z29-U29) -> 1174.5455 | AR29: =(AQ29*1.81818182) -> 0 | AT29: =AS29-DATE(YEAR(AS29),1,1)+1 -> 0
D30: 2010 | E30: =IF(G30/50 = 0, "", G30/50) -> 159.92727 | F30: =IF(MAX(J30,N30,S30,X30,AC30,AH30) = 0, "", MAX(J30,N30,S30,X30,AC30,AH30)) -> 98.181818 | G30: =SUMIF($Q$2:$AU$2, "Partial Area", $Q30:$AU30) -> 7996.3636 | H30: =IF(E30/F30 = 0, "", E30/F30) -> 1.6288889 | I30: 0 | J30: =I30/0.55 -> 0 | K30: 40179 | L30: =K30-DATE(YEAR(K30),1,1)+1 -> 1 | M30: 42 | N30: =(M30*1.81818182) -> 76.363636 | O30: 40247 | P30: =O30-DATE(YEAR(O30),1,1)+1 -> 69 | Q30: =((N30+J30)/2)*(P30-L30) -> 2596.3636 | R30: 54 | S30: =(R30*1.81818182) -> 98.181818 | T30: 40283 | U30: =T30-DATE(YEAR(T30),1,1)+1 -> 105 | V30: =((S30+N30)/2)*(U30-P30) -> 3141.8182 | W30: 0 | X30: =(W30*1.81818182) -> 0 | Y30: 40329 | Z30: =Y30-DATE(YEAR(Y30),1,1)+1 -> 151 | AA30: =((X30+S30)/2)*(Z30-U30) -> 2258.1818 | AR30: =(AQ30*1.81818182) -> 0 | AT30: =AS30-DATE(YEAR(AS30),1,1)+1 -> 0
D31: 2011 | E31: =IF(G31/50 = 0, "", G31/50) -> 253.38182 | F31: =IF(MAX(J31,N31,S31,X31,AC31,AH31) = 0, "", MAX(J31,N31,S31,X31,AC31,AH31)) -> 187.27273 | G31: =SUMIF($Q$2:$AU$2, "Partial Area", $Q31:$AU31) -> 12669.091 | H31: =IF(E31/F31 = 0, "", E31/F31) -> 1.3530097 | I31: 0 | J31: =I31/0.55 -> 0 | K31: 40544 | L31: =K31-DATE(YEAR(K31),1,1)+1 -> 1 | M31: 68 | N31: =(M31*1.81818182) -> 123.63636 | O31: 40630 | P31: =O31-DATE(YEAR(O31),1,1)+1 -> 87 | Q31: =((N31+J31)/2)*(P31-L31) -> 5316.3636 | R31: 103 | S31: =(R31*1.81818182) -> 187.27273 | T31: 40652 | U31: =T31-DATE(YEAR(T31),1,1)+1 -> 109 | V31: =((S31+N31)/2)*(U31-P31) -> 3420 | W31: 0 | X31: =(W31*1.81818182) -> 0 | Y31: 40694 | Z31: =Y31-DATE(YEAR(Y31),1,1)+1 -> 151 | AA31: =((X31+S31)/2)*(Z31-U31) -> 3932.7273 | AR31: =(AQ31*1.81818182) -> 0 | AT31: =AS31-DATE(YEAR(AS31),1,1)+1 -> 0
D32: 2012 | E32: =IF(G32/50 = 0, "", G32/50) -> 140.16364 | F32: =IF(MAX(J32,N32,S32,X32,AC32,AH32) = 0, "", MAX(J32,N32,S32,X32,AC32,AH32)) -> 76.363636 | G32: =SUMIF($Q$2:$AU$2, "Partial Area", $Q32:$AU32) -> 7008.1818 | H32: =IF(E32/F32 = 0, "", E32/F32) -> 1.8354762 | I32: 0 | J32: =I32/0.55 -> 0 | K32: 40909 | L32: =K32-DATE(YEAR(K32),1,1)+1 -> 1 | M32: 35 | N32: =(M32*1.81818182) -> 63.636364 | O32: 40991 | P32: =O32-DATE(YEAR(O32),1,1)+1 -> 83 | Q32: =((N32+J32)/2)*(P32-L32) -> 2609.0909 | R32: 39 | S32: =(R32*1.81818182) -> 70.909091 | T32: 41021 | U32: =T32-DATE(YEAR(T32),1,1)+1 -> 113 | V32: =((S32+N32)/2)*(U32-P32) -> 2018.1818 | W32: 42 | X32: =(W32*1.81818182) -> 76.363636 | Y32: 41036 | Z32: =Y32-DATE(YEAR(Y32),1,1)+1 -> 128 | AA32: =((X32+S32)/2)*(Z32-U32) -> 1104.5455 | AB32: 27 | AC32: =(AB32*1.81818182) -> 49.090909 | AD32: 41054 | AE32: =AD32-DATE(YEAR(AD32),1,1)+1 -> 146 | AF32: =((AC32+X32)/2)*(AE32-Z32) -> 1129.0909 | AG32: 0 | AH32: =(AG32*1.81818182) -> 0 | AI32: 41060 | AJ32: =AI32-DATE(YEAR(AI32),1,1)+1 -> 152 | AK32: =((AH32+AC32)/2)*(AJ32-AE32) -> 147.27273 | AR32: =(AQ32*1.81818182) -> 0 | AT32: =AS32-DATE(YEAR(AS32),1,1)+1 -> 0
D33: 2013 | E33: =IF(G33/50 = 0, "", G33/50) -> 297.8 | F33: =IF(MAX(J33,N33,S33,X33,AC33,AH33) = 0, "", MAX(J33,N33,S33,X33,AC33,AH33)) -> 169.09091 | G33: =SUMIF($Q$2:$AU$2, "Partial Area", $Q33:$AU33) -> 14890 | H33: =IF(E33/F33 = 0, "", E33/F33) -> 1.7611828 | I33: 0 | J33: =I33/0.55 -> 0 | K33: 41275 | L33: =K33-DATE(YEAR(K33),1,1)+1 -> 1 | M33: 84 | N33: =(M33*1.81818182) -> 152.72727 | O33: 41359 | P33: =O33-DATE(YEAR(O33),1,1)+1 -> 85 | Q33: =((N33+J33)/2)*(P33-L33) -> 6414.5455 | R33: 87 | S33: =(R33*1.81818182) -> 158.18182 | T33: 41360 | U33: =T33-DATE(YEAR(T33),1,1)+1 -> 86 | V33: =((S33+N33)/2)*(U33-P33) -> 155.45455 | W33: 93 | X33: =(W33*1.81818182) -> 169.09091 | Y33: 41381 | Z33: =Y33-DATE(YEAR(Y33),1,1)+1 -> 107 | AA33: =((X33+S33)/2)*(Z33-U33) -> 3436.3636 | AB33: 89 | AC33: =(AB33*1.81818182) -> 161.81818 | AD33: 41389 | AE33: =AD33-DATE(YEAR(AD33),1,1)+1 -> 115 | AF33: =((AC33+X33)/2)*(AE33-Z33) -> 1323.6364 | AG33: 89 | AH33: =(AG33*1.81818182) -> 161.81818 | AI33: 41397 | AJ33: =AI33-DATE(YEAR(AI33),1,1)+1 -> 123 | AK33: =((AH33+AC33)/2)*(AJ33-AE33) -> 1294.5455 | AL33: 0 | AM33: =(AL33*1.81818182) -> 0 | AN33: 41425 | AO33: =AN33-DATE(YEAR(AN33),1,1)+1 -> 151 | AP33: =((AM33+AH33)/2)*(AO33-AJ33) -> 2265.4545 | AR33: =(AQ33*1.81818182) -> 0 | AT33: =AS33-DATE(YEAR(AS33),1,1)+1 -> 0
D34: 2014 | E34: =IF(G34/50 = 0, "", G34/50) -> 164.36364 | F34: =IF(MAX(J34,N34,S34,X34,AC34,AH34) = 0, "", MAX(J34,N34,S34,X34,AC34,AH34)) -> 123.63636 | G34: =SUMIF($Q$2:$AU$2, "Partial Area", $Q34:$AU34) -> 8218.1818 | H34: =IF(E34/F34 = 0, "", E34/F34) -> 1.3294118 | I34: 0 | J34: =I34/0.55 -> 0 | K34: 41640 | L34: =K34-DATE(YEAR(K34),1,1)+1 -> 1 | M34: 39 | N34: =(M34*1.81818182) -> 70.909091 | O34: 41723 | P34: =O34-DATE(YEAR(O34),1,1)+1 -> 84 | Q34: =((N34+J34)/2)*(P34-L34) -> 2942.7273 | R34: 68 | S34: =(R34*1.81818182) -> 123.63636 | T34: 41740 | U34: =T34-DATE(YEAR(T34),1,1)+1 -> 101 | V34: =((S34+N34)/2)*(U34-P34) -> 1653.6364 | W34: 62 | X34: =(W34*1.81818182) -> 112.72727 | Y34: 41753 | Z34: =Y34-DATE(YEAR(Y34),1,1)+1 -> 114 | AA34: =((X34+S34)/2)*(Z34-U34) -> 1536.3636 | AB34: 0 | AC34: =(AB34*1.81818182) -> 0 | AD34: 41790 | AE34: =AD34-DATE(YEAR(AD34),1,1)+1 -> 151 | AF34: =((AC34+X34)/2)*(AE34-Z34) -> 2085.4545 | AM34: =(AL34*1.81818182) -> 0 | AR34: =(AQ34*1.81818182) -> 0 | AT34: =AS34-DATE(YEAR(AS34),1,1)+1 -> 0
D35: 2015 | E35: =IF(G35/50 = 0, "", G35/50) -> 330.03636 | F35: =IF(MAX(J35,N35,S35,X35,AC35,AH35) = 0, "", MAX(J35,N35,S35,X35,AC35,AH35)) -> 198.18182 | G35: =SUMIF($Q$2:$AU$2, "Partial Area", $Q35:$AU35) -> 16501.818 | H35: =IF(E35/F35 = 0, "", E35/F35) -> 1.6653211 | I35: 0 | J35: =I35/0.55 -> 0 | K35: 42005 | L35: =K35-DATE(YEAR(K35),1,1)+1 -> 1 | M35: 109 | N35: =(M35*1.81818182) -> 198.18182 | O35: 42090 | P35: =O35-DATE(YEAR(O35),1,1)+1 -> 86 | Q35: =((N35+J35)/2)*(P35-L35) -> 8422.7273 | R35: 106 | S35: =(R35*1.81818182) -> 192.72727 | T35: 42102 | U35: =T35-DATE(YEAR(T35),1,1)+1 -> 98 | V35: =((S35+N35)/2)*(U35-P35) -> 2345.4545 | W35: 81 | X35: =(W35*1.81818182) -> 147.27273 | Y35: 42121 | Z35: =Y35-DATE(YEAR(Y35),1,1)+1 -> 117 | AA35: =((X35+S35)/2)*(Z35-U35) -> 3230 | AB35: 0 | AC35: =(AB35*1.81818182) -> 0 | AD35: 42155 | AE35: =AD35-DATE(YEAR(AD35),1,1)+1 -> 151 | AF35: =((AC35+X35)/2)*(AE35-Z35) -> 2503.6364 | AM35: =(AL35*1.81818182) -> 0 | AR35: =(AQ35*1.81818182) -> 0 | AT35: =AS35-DATE(YEAR(AS35),1,1)+1 -> 0
D36: 2016 | E36: =IF(G36/50 = 0, "", G36/50) -> 278.12727 | F36: =IF(MAX(J36,N36,S36,X36,AC36,AH36) = 0, "", MAX(J36,N36,S36,X36,AC36,AH36)) -> 174.54545 | G36: =SUMIF($Q$2:$AU$2, "Partial Area", $Q36:$AU36) -> 13906.364 | H36: =IF(E36/F36 = 0, "", E36/F36) -> 1.5934375 | I36: 0 | J36: =I36/0.55 -> 0 | K36: 42370 | L36: =K36-DATE(YEAR(K36),1,1)+1 -> 1 | M36: 81 | N36: =(M36*1.81818182) -> 147.27273 | O36: 42456 | P36: =O36-DATE(YEAR(O36),1,1)+1 -> 87 | Q36: =((N36+J36)/2)*(P36-L36) -> 6332.7273 | R36: 94 | S36: =(R36*1.81818182) -> 170.90909 | T36: 42467 | U36: =T36-DATE(YEAR(T36),1,1)+1 -> 98 | V36: =((S36+N36)/2)*(U36-P36) -> 1750 | W36: 96 | X36: =(W36*1.81818182) -> 174.54545 | Y36: 42480 | Z36: =Y36-DATE(YEAR(Y36),1,1)+1 -> 111 | AA36: =((X36+S36)/2)*(Z36-U36) -> 2245.4545 | AB36: 0 | AC36: =(AB36*1.81818182) -> 0 | AD36: 42521 | AE36: =AD36-DATE(YEAR(AD36),1,1)+1 -> 152 | AF36: =((AC36+X36)/2)*(AE36-Z36) -> 3578.1818 | AM36: =(AL36*1.81818182) -> 0 | AR36: =(AQ36*1.81818182) -> 0 | AT36: =AS36-DATE(YEAR(AS36),1,1)+1 -> 0
D37: 2017 | E37: =IF(G37/50 = 0, "", G37/50) -> 138.36364 | F37: =IF(MAX(J37,N37,S37,X37,AC37,AH37) = 0, "", MAX(J37,N37,S37,X37,AC37,AH37)) -> 74.545455 | G37: =SUMIF($Q$2:$AU$2, "Partial Area", $Q37:$AU37) -> 6918.1818 | H37: =IF(E37/F37 = 0, "", E37/F37) -> 1.8560976 | I37: 0 | J37: =I37/0.55 -> 0 | K37: 42736 | L37: =K37-DATE(YEAR(K37),1,1)+1 -> 1 | M37: 41 | N37: =(M37*1.81818182) -> 74.545455 | O37: 42803 | P37: =O37-DATE(YEAR(O37),1,1)+1 -> 68 | Q37: =((N37+J37)/2)*(P37-L37) -> 2497.2727 | R37: 34 | S37: =(R37*1.81818182) -> 61.818182 | T37: 42829 | U37: =T37-DATE(YEAR(T37),1,1)+1 -> 94 | V37: =((S37+N37)/2)*(U37-P37) -> 1772.7273 | W37: 35 | X37: =(W37*1.81818182) -> 63.636364 | Y37: 42856 | Z37: =Y37-DATE(YEAR(Y37),1,1)+1 -> 121 | AA37: =((X37+S37)/2)*(Z37-U37) -> 1693.6364 | AB37: 0 | AC37: =(AB37*1.81818182) -> 0 | AD37: 42886 | AE37: =AD37-DATE(YEAR(AD37),1,1)+1 -> 151 | AF37: =((AC37+X37)/2)*(AE37-Z37) -> 954.54546 | AM37: =(AL37*1.81818182) -> 0 | AR37: =(AQ37*1.81818182) -> 0 | AT37: =AS37-DATE(YEAR(AS37),1,1)+1 -> 0
D38: 2018 | E38: =IF(G38/50 = 0, "", G38/50) -> 57.781818 | F38: =IF(MAX(J38,N38,S38,X38,AC38,AH38) = 0, "", MAX(J38,N38,S38,X38,AC38,AH38)) -> 32.727273 | G38: =SUMIF($Q$2:$AU$2, "Partial Area", $Q38:$AU38) -> 2889.0909 | H38: =IF(E38/F38 = 0, "", E38/F38) -> 1.7655556 | I38: 0 | J38: =I38/0.55 -> 0 | K38: 43101 | L38: =K38-DATE(YEAR(K38),1,1)+1 -> 1 | M38: 18 | N38: =(M38*1.81818182) -> 32.727273 | O38: 43175 | P38: =O38-DATE(YEAR(O38),1,1)+1 -> 75 | Q38: =((N38+J38)/2)*(P38-L38) -> 1210.9091 | R38: 16 | S38: =(R38*1.81818182) -> 29.090909 | T38: 43210 | U38: =T38-DATE(YEAR(T38),1,1)+1 -> 110 | V38: =((S38+N38)/2)*(U38-P38) -> 1081.8182 | W38: 0 | X38: =(W38*1.81818182) -> 0 | Y38: 43251 | Z38: =Y38-DATE(YEAR(Y38),1,1)+1 -> 151 | AA38: =((X38+S38)/2)*(Z38-U38) -> 596.36364 | AM38: =(AL38*1.81818182) -> 0 | AR38: =(AQ38*1.81818182) -> 0 | AT38: =AS38-DATE(YEAR(AS38),1,1)+1 -> 0
D39: 2019 | E39: =IF(G39/50 = 0, "", G39/50) -> 134.85455 | F39: =IF(MAX(J39,N39,S39,X39,AC39,AH39) = 0, "", MAX(J39,N39,S39,X39,AC39,AH39)) -> 81.818182 | G39: =SUMIF($Q$2:$AU$2, "Partial Area", $Q39:$AU39) -> 6742.7273 | H39: =IF(E39/F39 = 0, "", E39/F39) -> 1.6482222 | I39: 0 | J39: =I39/0.55 -> 0 | K39: 43466 | L39: =K39-DATE(YEAR(K39),1,1)+1 -> 1 | M39: 45 | N39: =(M39*1.81818182) -> 81.818182 | O39: 43557 | P39: =O39-DATE(YEAR(O39),1,1)+1 -> 92 | Q39: =((N39+J39)/2)*(P39-L39) -> 3722.7273 | R39: 38 | S39: =(R39*1.81818182) -> 69.090909 | T39: 43581 | U39: =T39-DATE(YEAR(T39),1,1)+1 -> 116 | V39: =((S39+N39)/2)*(U39-P39) -> 1810.9091 | W39: 0 | X39: =(W39*1.81818182) -> 0 | Y39: 43616 | Z39: =Y39-DATE(YEAR(Y39),1,1)+1 -> 151 | AA39: =((X39+S39)/2)*(Z39-U39) -> 1209.0909 | AM39: =(AL39*1.81818182) -> 0 | AR39: =(AQ39*1.81818182) -> 0 | AT39: =AS39-DATE(YEAR(AS39),1,1)+1 -> 0
D40: 2020 | E40: =IF(G40/50 = 0, "", G40/50) -> 56.636364 | F40: =IF(MAX(J40,N40,S40,X40,AC40,AH40) = 0, "", MAX(J40,N40,S40,X40,AC40,AH40)) -> 50.909091 | G40: =SUMIF($Q$2:$AU$2, "Partial Area", $Q40:$AU40) -> 2831.8182 | H40: =IF(E40/F40 = 0, "", E40/F40) -> 1.1125 | I40: 0 | J40: =I40/0.55 -> 0 | K40: 43831 | L40: =K40-DATE(YEAR(K40),1,1)+1 -> 1 | M40: 7 | N40: =(M40*1.81818182) -> 12.727273 | O40: 43895 | P40: =O40-DATE(YEAR(O40),1,1)+1 -> 65 | Q40: =((N40+J40)/2)*(P40-L40) -> 407.27273 | R40: 28 | S40: =(R40*1.81818182) -> 50.909091 | T40: 43928 | U40: =T40-DATE(YEAR(T40),1,1)+1 -> 98 | V40: =((S40+N40)/2)*(U40-P40) -> 1050 | W40: 0 | X40: =(W40*1.81818182) -> 0 | Y40: 43982 | Z40: =Y40-DATE(YEAR(Y40),1,1)+1 -> 152 | AA40: =((X40+S40)/2)*(Z40-U40) -> 1374.5455 | AM40: =(AL40*1.81818182) -> 0 | AR40: =(AQ40*1.81818182) -> 0 | AT40: =AS40-DATE(YEAR(AS40),1,1)+1 -> 0
...

Sheet Summary Charts
P70: Repeat X axis 0-9 4 times with 2002-2007, 2008-2013, 2014-2019, 2020-2024

Sheet Solving Unknown Survey Sections
C1: Survey Area and spatial distribution tool Solve for unknown survey sections
C2: Solve for unknown survey sections
C5: 1 | D5: 2 | E5: 3 | F5: 4 | G5: 5 | J5: 1 | K5: 2 | L5: 3 | M5: 4 | N5: 5
C6: Fraction of fish in each section (from regression) | J6: Fraction of fish in each section (from all survey average)
C7: Section 1 | D7: Section 2 | E7: Section 3 | F7: Section 1 and 2 | G7: Section 2 and 3 | J7: Section 1 | K7: Section 2 | L7: Section 3 | M7: Section 1 and 2 | N7: Section 2 and 3
A8: Day of run | C8: Lower | D8: Middle | E8: Upper | F8: Lower and Middle | G8: Upper and Middle | J8: Lower | K8: Middle | L8: Upper | M8: Lower and Middle | N8: Upper and Middle
A9: 1 | C9: =((0.003)*A9) -> 0.003 | D9: =((-0.0039)*A9)+0.8478 -> 0.8439 | E9: =(0.0002*A9)+0.1914 -> 0.1916 | F9: =C9+D9 -> 0.8469 | G9: =D9+E9 -> 1.0355 | J9: 0.21 | K9: 0.5 | L9: 0.28 | M9: =J9+K9 -> 0.71 | N9: =K9+L9 -> 0.78
A10: 2 | C10: =((0.003)*A10) -> 0.006 | D10: =((-0.0039)*A10)+0.8478 -> 0.84 | E10: =(0.0002*A10)+0.1914 -> 0.1918 | F10: =C10+D10 -> 0.846 | G10: =D10+E10 -> 1.0318 | J10: 0.21 | K10: 0.5 | L10: 0.28 | M10: =J10+K10 -> 0.71 | N10: =K10+L10 -> 0.78
A11: 3 | C11: =((0.003)*A11) -> 0.009 | D11: =((-0.0039)*A11)+0.8478 -> 0.8361 | E11: =(0.0002*A11)+0.1914 -> 0.192 | F11: =C11+D11 -> 0.8451 | G11: =D11+E11 -> 1.0281 | J11: 0.21 | K11: 0.5 | L11: 0.28 | M11: =J11+K11 -> 0.71 | N11: =K11+L11 -> 0.78
A12: 4 | C12: =((0.003)*A12) -> 0.012 | D12: =((-0.0039)*A12)+0.8478 -> 0.8322 | E12: =(0.0002*A12)+0.1914 -> 0.1922 | F12: =C12+D12 -> 0.8442 | G12: =D12+E12 -> 1.0244 | J12: 0.21 | K12: 0.5 | L12: 0.28 | M12: =J12+K12 -> 0.71 | N12: =K12+L12 -> 0.78
A13: 5 | C13: =((0.003)*A13) -> 0.015 | D13: =((-0.0039)*A13)+0.8478 -> 0.8283 | E13: =(0.0002*A13)+0.1914 -> 0.1924 | F13: =C13+D13 -> 0.8433 | G13: =D13+E13 -> 1.0207 | J13: 0.21 | K13: 0.5 | L13: 0.28 | M13: =J13+K13 -> 0.71 | N13: =K13+L13 -> 0.78
A14: 6 | C14: =((0.003)*A14) -> 0.018 | D14: =((-0.0039)*A14)+0.8478 -> 0.8244 | E14: =(0.0002*A14)+0.1914 -> 0.1926 | F14: =C14+D14 -> 0.8424 | G14: =D14+E14 -> 1.017 | J14: 0.21 | K14: 0.5 | L14: 0.28 | M14: =J14+K14 -> 0.71 | N14: =K14+L14 -> 0.78
A15: 7 | C15: =((0.003)*A15) -> 0.021 | D15: =((-0.0039)*A15)+0.8478 -> 0.8205 | E15: =(0.0002*A15)+0.1914 -> 0.1928 | F15: =C15+D15 -> 0.8415 | G15: =D15+E15 -> 1.0133 | J15: 0.21 | K15: 0.5 | L15: 0.28 | M15: =J15+K15 -> 0.71 | N15: =K15+L15 -> 0.78
A16: 8 | C16: =((0.003)*A16) -> 0.024 | D16: =((-0.0039)*A16)+0.8478 -> 0.8166 | E16: =(0.0002*A16)+0.1914 -> 0.193 | F16: =C16+D16 -> 0.8406 | G16: =D16+E16 -> 1.0096 | J16: 0.21 | K16: 0.5 | L16: 0.28 | M16: =J16+K16 -> 0.71 | N16: =K16+L16 -> 0.78
A17: 9 | C17: =((0.003)*A17) -> 0.027 | D17: =((-0.0039)*A17)+0.8478 -> 0.8127 | E17: =(0.0002*A17)+0.1914 -> 0.1932 | F17: =C17+D17 -> 0.8397 | G17: =D17+E17 -> 1.0059 | J17: 0.21 | K17: 0.5 | L17: 0.28 | M17: =J17+K17 -> 0.71 | N17: =K17+L17 -> 0.78
A18: 10 | C18: =((0.003)*A18) -> 0.03 | D18: =((-0.0039)*A18)+0.8478 -> 0.8088 | E18: =(0.0002*A18)+0.1914 -> 0.1934 | F18: =C18+D18 -> 0.8388 | G18: =D18+E18 -> 1.0022 | J18: 0.21 | K18: 0.5 | L18: 0.28 | M18: =J18+K18 -> 0.71 | N18: =K18+L18 -> 0.78
A19: 11 | C19: =((0.003)*A19) -> 0.033 | D19: =((-0.0039)*A19)+0.8478 -> 0.8049 | E19: =(0.0002*A19)+0.1914 -> 0.1936 | F19: =C19+D19 -> 0.8379 | G19: =D19+E19 -> 0.9985 | J19: 0.21 | K19: 0.5 | L19: 0.28 | M19: =J19+K19 -> 0.71 | N19: =K19+L19 -> 0.78
A20: 12 | C20: =((0.003)*A20) -> 0.036 | D20: =((-0.0039)*A20)+0.8478 -> 0.801 | E20: =(0.0002*A20)+0.1914 -> 0.1938 | F20: =C20+D20 -> 0.837 | G20: =D20+E20 -> 0.9948 | J20: 0.21 | K20: 0.5 | L20: 0.28 | M20: =J20+K20 -> 0.71 | N20: =K20+L20 -> 0.78
... A52: 44 | C52: =((0.003)*A52) -> 0.132 | D52: =((-0.0039)*A52)+0.8478 -> 0.6762 | E52: =(0.0002*A52)+0.1914 -> 0.2002 | F52: =C52+D52 -> 0.8082 | G52: =D52+E52 -> 0.8764 | J52: 0.21 | K52: 0.5 | L52: 0.28 | M52: =J52+K52 -> 0.71 | N52: =K52+L52 -> 0.78
C53: =((0.003)*A53) -> 0 | D53: =((-0.0039)*A53)+0.8478 -> 0.8478 | E53: =(0.0002*A53)+0.1914 -> 0.1914 | F53: =C53+D53 -> 0.8478 | G53: =D53+E53 -> 1.0392 | J53: 0.21 | K53: 0.5 | L53: 0.28 | M53: =J53+K53 -> 0.71 | N53: =K53+L53 -> 0.78
A54: 45 | C54: =((0.003)*A54) -> 0.135 | D54: =((-0.0039)*A54)+0.8478 -> 0.6723 | E54: =(0.0002*A54)+0.1914 -> 0.2004 | F54: =C54+D54 -> 0.8073 | G54: =D54+E54 -> 0.8727 | J54: 0.21 | K54: 0.5 | L54: 0.28 | M54: =J54+K54 -> 0.71 | N54: =K54+L54 -> 0.78
A55: 46 | C55: =((0.003)*A55) -> 0.138 | D55: =((-0.0039)*A55)+0.8478 -> 0.6684 | E55: =(0.0002*A55)+0.1914 -> 0.2006 | F55: =C55+D55 -> 0.8064 | G55: =D55+E55 -> 0.869 | J55: 0.21 | K55: 0.5 | L55: 0.28 | M55: =J55+K55 -> 0.71 | N55: =K55+L55 -> 0.78
A56: 47 | C56: =((0.003)*A56) -> 0.141 | D56: =((-0.0039)*A56)+0.8478 -> 0.6645 | E56: =(0.0002*A56)+0.1914 -> 0.2008 | F56: =C56+D56 -> 0.8055 | G56: =D56+E56 -> 0.8653 | J56: 0.21 | K56: 0.5 | L56: 0.28 | M56: =J56+K56 -> 0.71 | N56: =K56+L56 -> 0.78
A57: 48 | C57: =((0.003)*A57) -> 0.144 | D57: =((-0.0039)*A57)+0.8478 -> 0.6606 | E57: =(0.0002*A57)+0.1914 -> 0.201 | F57: =C57+D57 -> 0.8046 | G57: =D57+E57 -> 0.8616 | J57: 0.21 | K57: 0.5 | L57: 0.28 | M57: =J57+K57 -> 0.71 | N57: =K57+L57 -> 0.78
A58: 49 | C58: =((0.003)*A58) -> 0.147 | D58: =((-0.0039)*A58)+0.8478 -> 0.6567 | E58: =(0.0002*A58)+0.1914 -> 0.2012 | F58: =C58+D58 -> 0.8037 | G58: =D58+E58 -> 0.8579 | J58: 0.21 | K58: 0.5 | L58: 0.28 | M58: =J58+K58 -> 0.71 | N58: =K58+L58 -> 0.78
A59: 50 | C59: =((0.003)*A59) -> 0.15 | D59: =((-0.0039)*A59)+0.8478 -> 0.6528 | E59: =(0.0002*A59)+0.1914 -> 0.2014 | F59: =C59+D59 -> 0.8028 | G59: =D59+E59 -> 0.8542 | J59: 0.21 | K59: 0.5 | L59: 0.28 | M59: =J59+K59 -> 0.71 | N59: =K59+L59 -> 0.78
A60: 51 | C60: =((0.003)*A60) -> 0.153 | D60: =((-0.0039)*A60)+0.8478 -> 0.6489 | E60: =(0.0002*A60)+0.1914 -> 0.2016 | F60: =C60+D60 -> 0.8019 | G60: =D60+E60 -> 0.8505 | J60: 0.21 | K60: 0.5 | L60: 0.28 | M60: =J60+K60 -> 0.71 | N60: =K60+L60 -> 0.78
A61: 52 | C61: =((0.003)*A61) -> 0.156 | D61: =((-0.0039)*A61)+0.8478 -> 0.645 | E61: =(0.0002*A61)+0.1914 -> 0.2018 | F61: =C61+D61 -> 0.801 | G61: =D61+E61 -> 0.8468 | J61: 0.21 | K61: 0.5 | L61: 0.28 | M61: =J61+K61 -> 0.71 | N61: =K61+L61 -> 0.78
A62: 53 | C62: =((0.003)*A62) -> 0.159 | D62: =((-0.0039)*A62)+0.8478 -> 0.6411 | E62: =(0.0002*A62)+0.1914 -> 0.202 | F62: =C62+D62 -> 0.8001 | G62: =D62+E62 -> 0.8431 | J62: 0.21 | K62: 0.5 | L62: 0.28 | M62: =J62+K62 -> 0.71 | N62: =K62+L62 -> 0.78
A63: 54 | C63: =((0.003)*A63) -> 0.162 | D63: =((-0.0039)*A63)+0.8478 -> 0.6372 | E63: =(0.0002*A63)+0.1914 -> 0.2022 | F63: =C63+D63 -> 0.7992 | G63: =D63+E63 -> 0.8394 | J63: 0.21 | K63: 0.5 | L63: 0.28 | M63: =J63+K63 -> 0.71 | N63: =K63+L63 -> 0.78
A64: 55 | C64: =((0.003)*A64) -> 0.165 | D64: =((-0.0039)*A64)+0.8478 -> 0.6333 | E64: =(0.0002*A64)+0.1914 -> 0.2024 | F64: =C64+D64 -> 0.7983 | G64: =D64+E64 -> 0.8357 | J64: 0.21 | K64: 0.5 | L64: 0.28 | M64: =J64+K64 -> 0.71 | N64: =K64+L64 -> 0.78
A65: 56 | C65: =((0.003)*A65) -> 0.168 | D65: =((-0.0039)*A65)+0.8478 -> 0.6294 | E65: =(0.0002*A65)+0.1914 -> 0.2026 | F65: =C65+D65 -> 0.7974 | G65: =D65+E65 -> 0.832 | J65: 0.21 | K65: 0.5 | L65: 0.28 | M65: =J65+K65 -> 0.71 | N65: =K65+L65 -> 0.78
... A165: 151 | C165: =((0.003)*A165) -> 0.453 | D165: =((-0.0039)*A165)+0.8478 -> 0.2589 | E165: =(0.0002*A165)+0.1914 -> 0.2216 | F165: =C165+D165 -> 0.7119 | G165: =D165+E165 -> 0.4805 | J165: 0.21 | K165: 0.5 | L165: 0.28 | M165: =J165+K165 -> 0.71 | N165: =K165+L165 -> 0.78

Sheet Percent of Run
F4: Percent of run
E5: Day of run
E6: 1 | F6: =E6*0.009 -> 0.009
E7: 2 | F7: =E7*0.009 -> 0.018
E8: 3 | F8: =E8*0.009 -> 0.027
E9: 4 | F9: =E9*0.009 -> 0.036
E10: 5 | F10: =E10*0.009 -> 0.045
E11: 6 | F11: =E11*0.009 -> 0.054
E12: 7 | F12: =E12*0.009 -> 0.063
E13: 8 | F13: =E13*0.009 -> 0.072
E14: 9 | F14: =E14*0.009 -> 0.081
E15: 10 | F15: =E15*0.009 -> 0.09
E16: 11 | F16: =E16*0.009 -> 0.099
E17: 12 | F17: =E17*0.009 -> 0.108
... E122: 111 | F122: =E122*0.009 -> 0.999
E123: 112 | F123: 1
E124: 113 | F124: 1
E125: 114 | F125: 1
E126: 115 | F126: 1
E127: 116 | F127: 1
E128: 117 | F128: 1
E129: 118 | F129: 1
E130: 119 | F130: 1
E131: 120 | F131: 1
E132: 121 | F132: 1
E133: 122 | F133: 1
E134: 123 | F134: 1
E135: 124
E136: 125
E137: 126
E138: 127
E139: 128
E140: 129
E141: 130
E142: 131
E143: 132
E144: 133
E145: 134
E146: 135
... E162: 151

Sheet Time and Area Standardization
B1: This area corrects for spatial (ie incomplete surveys) and temporal (ie non peak time) adjustments as if the survey was completed as a whole stream and at peak time | H1: Spatially Calibrated (time variant) | Q1: Spatially Calibrated (Fixed ratio) scales results for whole stream | Z1: Temporally calibrated | AB1: RAW AUC | AC1: Res time= | AF1: 50 | AG1: OE calibrated - Relationship # | AH1: Fixed at | AI1: 0.55 | AJ1: AUC | AM1: Res time= | AN1: 50 | AQ1: Abundance estimates for 1982-2001, 2006, 2008, 2009 derived from average MLE / peak ratio using mean OE of 0.55 (2002-2011;2015-2016) or with Calibrated OE estimates (2012-2014) | AU1: OE calibrated - Relationship # | AW1: 1 | AZ1: Res time = | BA1: 50 | BB1: Time standardized | BE1: Area standardization
B2: Day | C2: Survey Date | D2: Unadjusted flow on survey day | E2: WSC - Average daily Q | F2: % Hatchery | G2: Spatially / temporally corected Sections (1,2,3) | H2: Section 1 and 2 | I2: factor | J2: estimate | K2: Section 2 | L2: factor | M2: estimate | N2: Section 2 and 3 | O2: factor | P2: estimate | Q2: Section 1 and 2 | R2: factor | S2: Sec 1,2,3 Abundance Estimate | T2: Section 2 | U2: factor | W2: Section 2 and 3 | X2: factor | Y2: Sec 1,2,3 Abundance Estimate | Z2: factor | AA2: Estimate | AB2: Partial Area | AC2: Population estimate (AUC) | AD2: Annual Peak count | AE2: Peak / population ratio | AF2: Annual AUC (fish days) | AG2: Corrected count | AH2: Survey Efficiency | AJ2: Partial Area | AK2: Steelhead Population Estimate (AUC - fixed at 50 days residence time and 0.55 observer efficiency, these data include spatially and temporally calibrated surveys for incomplete or non-peak surveys before 1998) | AL2: Annual Peak Count (observer efficiency of 0.55 applied, spatially and temporally calibrated for non-peak and incomplete historic surveys prior to 1998) | AM2: OE Adj Peak / population ratio | AN2: Annual AUC (fish days) | AO2: MLE estimate (OE Mean) | AP2: MLE peak count ratio (OE Mean) | AQ2: Abundance estimates derived from average MLE / peak ratio or with Calibrated OE estimates (2012-2014) | AR2: MLE with Priors | AS2: MLE peak count ratio (OE Mean) | AT2: Abundance from average MLE/peak ratio (2002 - 2016 - OE - Priors ) | AU2: Corrected count | AV2: Syurvey day / unadjusted flow | AW2: Survey Efficiency | AX2: Popn | AY2: Peak count population ratio | AZ2: Partial Area (fish/days) | BA2: Annual AUC (fish/days) | BC2: fraction of peak count | BD2: fraction of peak count | BE2: Section 1 (upper) | BG2: Section 2 (middle) | BI2: Section 3 (lower) | BK2: Section 4 (South F) | BL2: MLE Estimate
A4: 1982 | B4: =C4-DATE(YEAR(C4),1,1)+1 -> 1 | C4: 29952 | E4: =VLOOKUP(C4,'Historic Daily flows'!$A$1:$B$37941,2) -> 5.93 | G4: 0 | AG4: 0
A5: 1982 | B5: =C5-DATE(YEAR(C5),1,1)+1 -> 112 | C5: 30063 | E5: =VLOOKUP(C5,'Historic Daily flows'!$A$1:$B$37941,2) -> 10.1 | F5: 0.05 | G5: =AA5 -> 185.89744 | N5: 145 | O5: =VLOOKUP(B5,$CJ$101:$CP$257, 7) -> 0.6248 | P5: =N5/O5 -> 232.07426 | W5: 145 | X5: =VLOOKUP(B5,$CJ$98:$CV$254, 13) -> 0.78 | Y5: =W5/X5 -> 185.89744 | Z5: =VLOOKUP(B5,$CG$86:$CI$242,2) -> 1 | AA5: =Y5/Z5 -> 185.89744 | AB5: =0.5*($B6-$B4)*G5 -> 13942.308 | AC5: =AF5/$AF$1 -> 278.84615 | AD5: =G5 -> 185.89744 | AE5: =AC5/AD5 -> 1.5 | AF5: =AB5 -> 13942.308 | AG5: =G5/AH5 -> 337.99534 | AH5: =$AI$1 -> 0.55 | AJ5: =AB5/AH5 -> 25349.65 | AK5: =AN5/$AF$1 -> 506.99301 | AL5: =AD5/AH5 -> 337.99534 | AM5: =AK5/AL5 -> 1.5 | AN5: =AF5/AH5 -> 25349.65 | AQ5: =AL5*$AP$188 -> 0 | AT5: =AL5*$AS$177 -> 0
A6: 1982 | B6: =C6-DATE(YEAR(C6),1,1)+1 -> 151 | C6: 30102 | E6: =VLOOKUP(C6,'Historic Daily flows'!$A$1:$B$37941,2) -> 17.7 | G6: =AA6 -> 0 | AG6: =G6/AH6 -> 0 | AH6: =$AI$1 -> 0.55 | AJ6: =AB6/AH6 -> 0 | AL6: =AD6/AH6 -> 0 | AN6: =AF6/AH6 -> 0
A7: 1983 | B7: =C7-DATE(YEAR(C7),1,1)+1 -> 1 | C7: 30317 | E7: =VLOOKUP(C7,'Historic Daily flows'!$A$1:$B$37941,2) -> 6.27 | G7: 0 | AG7: =AHM77 -> 0 | AH7: =$AI$1 -> 0.55 | AJ7: =AB7/AH7 -> 0 | AL7: =AD7/AH7 -> 0 | AN7: =AF7/AH7 -> 0
A8: 1983 | B8: =C8-DATE(YEAR(C8),1,1)+1 -> 83 | C8: 30399 | E8: =VLOOKUP(C8,'Historic Daily flows'!$A$1:$B$37941,2) -> 9.44 | F8: 0.1 | G8: =S8 -> 212.67606 | H8: 151 | I8: =VLOOKUP(B8,$CJ$97:$CP$253, 6) -> 0.7749 | J8: =H8/I8 -> 194.86385 | Q8: 151 | R8: =VLOOKUP(B8,CJ61:CV227, 12) -> 0.71 | S8: =Q8/R8 -> 212.67606 | Z8: =VLOOKUP(B8,$CG$86:$CI$242,2) -> 0.729 | AA8: =S8/Z8 -> 291.7367 | AB8: =0.5*(B8-B7)*G8 -> 8719.7183 | AC8: =AF8/$AF$1 -> 461.34066 | AD8: =G10 -> 326.39062 | AE8: =AC8/AD8 -> 1.4134618 | AF8: =SUM(AB8:AB11) -> 23067.033 | AG8: =G8/AH8 -> 386.68374 | AH8: =$AI$1 -> 0.55 | AJ8: =AB8/AH8 -> 15854.033 | AK8: =AN8/$AN$1 -> 838.80121 | AL8: =AD8/AH8 -> 593.43749 | AM8: =AK8/AL8 -> 1.4134618 | AN8: =AF8/AH8 -> 41940.06 | AQ8: =AL8*$AP$188 -> 0 | AT8: =AL8*$AS$177 -> 0
A9: 1983 | B9: =C9-DATE(YEAR(C9),1,1)+1 -> 103 | C9: 30419 | E9: =VLOOKUP(C9,'Historic Daily flows'!$A$1:$B$37941,2) -> 6.98 | F9: 0.15 | G9: =Y9 -> 302.5641 | N9: 236 | O9: =VLOOKUP(B9,$CJ$101:$CP$257, 7) -> 0.6581 | P9: =N9/O9 -> 358.60811 | W9: 236 | X9: =VLOOKUP(B9,$CJ$98:$CV$254, 13) -> 0.78 | Y9: =W9/X9 -> 302.5641 | Z9: =VLOOKUP(B9,$CG$86:$CI$242,2) -> 0.927 | AA9: =Y9/Z9 -> 326.39062 | AB9: =((B9-B8)*G9)-((B9-B8)*(G9-G8)*0.5) -> 5152.4016 | AG9: =G9/AH9 -> 550.11655 | AH9: =$AI$1 -> 0.55 | AJ9: =AB9/AH9 -> 9368.0029 | AL9: =AD9/AH9 -> 0 | AN9: =AF9/AH9 -> 0
A10: 1983 | B10: =C10-DATE(YEAR(C10),1,1)+1 -> 112 | C10: 30428 | E10: =VLOOKUP(C10,'Historic Daily flows'!$A$1:$B$37941,2) -> 7.6 | F10: 0.15 | G10: =AA9 -> 326.39062 | AB10: =((B10-B9)*G10)-((B10-B9)*(G10-G9)*0.5) -> 2830.2962 | AG10: =G10/AH10 -> 593.43749 | AH10: =$AI$1 -> 0.55 | AJ10: =AB10/AH10 -> 5145.9932 | AL10: =AD10/AH10 -> 0 | AN10: =AF10/AH10 -> 0
A11: 1983 | B11: =C11-DATE(YEAR(C11),1,1)+1 -> 151 | C11: 30467 | E11: =VLOOKUP(C11,'Historic Daily flows'!$A$1:$B$37941,2) -> 11.3 | G11: 0 | AB11: =0.5*(B11-B10)*G10 -> 6364.617 | AG11: =G11/AH11 -> 0 | AH11: =$AI$1 -> 0.55 | AJ11: =AB11/AH11 -> 11572.031 | AL11: =AD11/AH11 -> 0 | AN11: =AF11/AH11 -> 0
A12: 1984 | B12: =C12-DATE(YEAR(C12),1,1)+1 -> 1 | C12: 30682 | E12: =VLOOKUP(C12,'Historic Daily flows'!$A$1:$B$37941,2) -> 13.7 | G12: =AA12 -> 0 | AG12: =G12/AH12 -> 0 | AH12: =$AI$1 -> 0.55 | AJ12: =AB12/AH12 -> 0 | AL12: =AD12/AH12 -> 0 | AN12: =AF12/AH12 -> 0
A13: 1984 | B13: =C13-DATE(YEAR(C13),1,1)+1 -> 93 | C13: 30774 | E13: =VLOOKUP(C13,'Historic Daily flows'!$A$1:$B$37941,2) -> 6.12 | F13: 0.26 | G13: =S13 -> 297.64706 | H13: 253 | I13: 0.85 | J13: =H13/I13 -> 297.64706 | Q13: 253 | R13: 0.85 | S13: =Q13/R13 -> 297.64706 | Z13: =VLOOKUP(B13,$CG$86:$CI$242,2) -> 0.837 | AA13: =S13/Z13 -> 355.61178 | AB13: =0.5*($B15-$B12)*$G13 -> 22472.353 | AC13: =AF13/$AF$1 -> 718.78742 | AD13: =G14 -> 355.61178 | AE13: =AC13/AD13 -> 2.02127 | AF13: =SUM(AB12:AB15) -> 35939.371 | AG13: =G13/AH13 -> 541.17647 | AH13: =$AI$1 -> 0.55 | AJ13: =AB13/AH13 -> 40858.824 | AK13: =AN13/$AF$1 -> 1306.8862 | AL13: =AD13/AH13 -> 646.56687 | AM13: =AK13/AL13 -> 2.02127 | AN13: =AF13/AH13 -> 65344.311 | AQ13: =AL13*$AP$188 -> 0 | AT13: =AL13*$AS$177 -> 0
A14: 1984 | B14: =C14-DATE(YEAR(C14),1,1)+1 -> 113 | C14: 30794 | E14: =VLOOKUP(C14,'Historic Daily flows'!$A$1:$B$37941,2) -> 9.81 | F14: 0.26 | G14: =AA13 -> 355.61178 | AB14: =((B14-B13)*G14)-((B14-B13)*(G14-G13)*0.5) -> 6532.5884 | AG14: =G14/AH14 -> 646.56687 | AH14: =$AI$1 -> 0.55 | AJ14: =AB14/AH14 -> 11877.433 | AL14: =AD14/AH14 -> 0 | AN14: =AF14/AH14 -> 0
A15: 1984 | B15: =C15-DATE(YEAR(C15),1,1)+1 -> 152 | C15: 30833 | E15: =VLOOKUP(C15,'Historic Daily flows'!$A$1:$B$37941,2) -> 13.1 | G15: =AA15 -> 0 | R15: hootons TO | AB15: =0.5*(B15-B14)*G14 -> 6934.4297 | AG15: =G15/AH15 -> 0 | AH15: =$AI$1 -> 0.55 | AJ15: =AB15/AH15 -> 12608.054 | AL15: =AD15/AH15 -> 0 | AN15: =AF15/AH15 -> 0
A16: 1985 | B16: =C16-DATE(YEAR(C16),1,1)+1 -> 1 | C16: 31048 | E16: =VLOOKUP(C16,'Historic Daily flows'!$A$1:$B$37941,2) -> 3.52 | G16: 0 | AG16: =G16/AH16 -> 0 | AH16: =$AI$1 -> 0.55 | AJ16: =AB16/AH16 -> 0 | AL16: =AD16/AH16 -> 0 | AN16: =AF16/AH16 -> 0
A17: 1985 | B17: =C17-DATE(YEAR(C17),1,1)+1 -> 101 | C17: 31148 | E17: =VLOOKUP(C17,'Historic Daily flows'!$A$1:$B$37941,2) -> 22.8 | F17: 0.28 | G17: 471 | S17: 471 | Z17: =VLOOKUP(B17,$CG$86:$CI$242,2) -> 0.909 | AA17: =S17/Z17 -> 518.15182 | AB17: =0.5*($B19-$B16)*$G17 -> 35325 | AC17: =AF17/$AF$1 -> 1017.3859 | AD17: =G18 -> 518.15182 | AE17: =AC17/AD17 -> 1.96349 | AF17: =SUM(AB17:AB19) -> 50869.295 | AG17: =G17/AH17 -> 856.36364 | AH17: =$AI$1 -> 0.55 | AJ17: =AB17/AH17 -> 64227.273 | AK17: =AN17/$AN$1 -> 1849.7926 | AL17: =AD17/AH17 -> 942.09421 | AM17: =AK17/AL17 -> 1.96349 | AN17: =AF17/AH17 -> 92489.628 | AQ17: =AL17*$AP$188 -> 0 | AT17: =AL17*$AS$177 -> 0
A18: 1985 | B18: =C18-DATE(YEAR(C18),1,1)+1 -> 112 | C18: 31159 | E18: =VLOOKUP(C18,'Historic Daily flows'!$A$1:$B$37941,2) -> 6.06 | F18: 0.28 | G18: =AA17 -> 518.15182 | AB18: =((B18-B17)*G18)-((B18-B17)*(G18-G17)*0.5) -> 5440.335 | AG18: =G18/AH18 -> 942.09421 | AH18: =$AI$1 -> 0.55 | AJ18: =AB18/AH18 -> 9891.5182 | AL18: =AD18/AH18 -> 0 | AN18: =AF18/AH18 -> 0
A19: 1985 | B19: =C19-DATE(YEAR(C19),1,1)+1 -> 151 | C19: 31198 | E19: =VLOOKUP(C19,'Historic Daily flows'!$A$1:$B$37941,2) -> 7.54 | G19: 0 | AB19: =0.5*(B19-B18)*G18 -> 10103.96 | AG19: =G19/AH19 -> 0 | AH19: =$AI$1 -> 0.55 | AJ19: =AB19/AH19 -> 18370.837 | AL19: =AD19/AH19 -> 0 | AN19: =AF19/AH19 -> 0
A20: 1986 | B20: =C20-DATE(YEAR(C20),1,1)+1 -> 1 | C20: 31413 | E20: =VLOOKUP(C20,'Historic Daily flows'!$A$1:$B$37941,2) -> 3.62 | G20: =AA20 -> 0 | AG20: =G20/AH20 -> 0 | AH20: =$AI$1 -> 0.55 | AJ20: =AB20/AH20 -> 0 | AL20: =AD20/AH20 -> 0 | AN20: =AF20/AH20 -> 0
A21: 1986 | B21: =C21-DATE(YEAR(C21),1,1)+1 -> 40 | C21: 31452 | E21: =VLOOKUP(C21,'Historic Daily flows'!$A$1:$B$37941,2) -> 9.15 | F21: =(F17+F25)/2 -> 0.365 | G21: =S21 -> 78.873239 | H21: 56 | I21: =VLOOKUP(B21,$CJ$97:$CP$253, 6) -> 0.8118 | J21: =H21/I21 -> 68.982508 | Q21: 56 | R21: =VLOOKUP(B21,CJ61:CV227, 12) -> 0.71 | S21: =Q21/R21 -> 78.873239 | Z21: =VLOOKUP(B21,$CG$86:$CI$242,2) -> 0.36 | AA21: =S21/Z21 -> 219.09233 | AB21: =0.5*($B23-$B20)*$G21 -> 5915.493 | AC21: =AF21/$AF$1 -> 418.29108 | AD21: =G22 -> 219.09233 | AE21: =AC21/AD21 -> 1.9092 | AF21: =SUM(AB21:AB23) -> 20914.554 | AG21: =G21/AH21 -> 143.40589 | AH21: =$AI$1 -> 0.55 | AJ21: =AB21/AH21 -> 10755.442 | AK21: =AN21/$AF$1 -> 760.52924 | AL21: =AD21/AH21 -> 398.34969 | AM21: =AK21/AL21 -> 1.9092 | AN21: =AF21/AH21 -> 38026.462 | AQ21: =AL21*$AP$188 -> 0 | AT21: =AL21*$AS$177 -> 0
A22: 1986 | B22: =C22-DATE(YEAR(C22),1,1)+1 -> 112 | C22: 31524 | E22: =VLOOKUP(C22,'Historic Daily flows'!$A$1:$B$37941,2) -> 7.04 | F22: =(F18+F27)/2 -> 0.14 | G22: =AA21 -> 219.09233 | AB22: =((B22-B21)*G22)-((B22-B21)*(G22-G21)*0.5) -> 10726.761 | AG22: =G22/AH22 -> 398.34969 | AH22: =$AI$1 -> 0.55 | AJ22: =AB22/AH22 -> 19503.201 | AL22: =AD22/AH22 -> 0 | AN22: =AF22/AH22 -> 0
A23: 1986 | B23: =C23-DATE(YEAR(C23),1,1)+1 -> 151 | C23: 31563 | E23: =VLOOKUP(C23,'Historic Daily flows'!$A$1:$B$37941,2) -> 9.22 | G23: =AA23 -> 0 | AB23: =0.5*(B23-B22)*G22 -> 4272.3005 | AG23: =G23/AH23 -> 0 | AH23: =$AI$1 -> 0.55 | AJ23: =AB23/AH23 -> 7767.819 | AL23: =AD23/AH23 -> 0 | AN23: =AF23/AH23 -> 0
A24: 1987 | B24: =C24-DATE(YEAR(C24),1,1)+1 -> 1 | C24: 31778 | E24: =VLOOKUP(C24,'Historic Daily flows'!$A$1:$B$37941,2) -> 34.6 | G24: 0 | AG24: =G24/AH24 -> 0 | AH24: =$AI$1 -> 0.55 | AJ24: =AB24/AH24 -> 0 | AL24: =AD24/AH24 -> 0 | AN24: =AF24/AH24 -> 0
A25: 1987 | B25: =C25-DATE(YEAR(C25),1,1)+1 -> 86 | C25: 31863 | E25: =VLOOKUP(C25,'Historic Daily flows'!$A$1:$B$37941,2) -> 7.49 | F25: 0.45 | G25: =V25 -> 328 | K25: 164 | L25: =VLOOKUP(B25,$CJ$101:$CR$257, 4) -> 0.5319 | M25: =K25/L25 -> 308.32863 | T25: 164 | U25: =VLOOKUP(B25,$CJ$101:$CV$257, 10) -> 0.5 | V25: =T25/U25 -> 328 | Z25: =VLOOKUP(B25,$CG$86:$CI$242,2) -> 0.729 | AA25: =V25/Z25 -> 449.93141 | AB25: =0.5*($B27-$B24)*$G25 -> 24600 | AC25: =AF25/$AF$1 -> 869.73542 | AD25: =G26 -> 449.93141 | AE25: =AC25/AD25 -> 1.93304 | AF25: =SUM(AB25:AB27) -> 43486.771 | AG25: =G25/AH25 -> 596.36364 | AH25: =$AI$1 -> 0.55 | AJ25: =AB25/AH25 -> 44727.273 | AK25: =AN25/$AN$1 -> 1581.3371 | AL25: =AD25/AH25 -> 818.05711 | AM25: =AK25/AL25 -> 1.93304 | AN25: =AF25/AH25 -> 79066.856 | AQ25: =AL25*$AP$188 -> 0 | AT25: =AL25*$AS$177 -> 0
A26: 1987 | B26: =C26-DATE(YEAR(C26),1,1)+1 -> 112 | C26: 31889 | E26: =VLOOKUP(C26,'Historic Daily flows'!$A$1:$B$37941,2) -> 6.98 | F26: 0.45 | G26: =AA25 -> 449.93141 | AB26: =((B26-B25)*G26)-((B26-B25)*(G26-G25)*0.5) -> 10113.108 | AG26: =G26/AH26 -> 818.05711 | AH26: =$AI$1 -> 0.55 | AJ26: =AB26/AH26 -> 18387.47 | AL26: =AD26/AH26 -> 0 | AN26: =AF26/AH26 -> 0
A27: 1987 | B27: =C27-DATE(YEAR(C27),1,1)+1 -> 151 | C27: 31928 | E27: =VLOOKUP(C27,'Historic Daily flows'!$A$1:$B$37941,2) -> 18.8 | G27: 0 | AB27: =0.5*(B27-B26)*G26 -> 8773.6626 | AG27: =G27/AH27 -> 0 | AH27: =$AI$1 -> 0.55 | AJ27: =AB27/AH27 -> 15952.114 | AL27: =AD27/AH27 -> 0 | AN27: =AF27/AH27 -> 0
A28: 1988 | B28: =C28-DATE(YEAR(C28),1,1)+1 -> 1 | C28: 32143 | E28: =VLOOKUP(C28,'Historic Daily flows'!$A$1:$B$37941,2) -> 3.28 | G28: =AA28 -> 0 | AG28: =G28/AH28 -> 0 | AH28: =$AI$1 -> 0.55 | AJ28: =AB28/AH28 -> 0 | AL28: =AD28/AH28 -> 0 | AN28: =AF28/AH28 -> 0
A29: 1988 | B29: =C29-DATE(YEAR(C29),1,1)+1 -> 55 | C29: 32197 | E29: =VLOOKUP(C29,'Historic Daily flows'!$A$1:$B$37941,2) -> 6.52 | F29: 0.23 | G29: =S29 -> 250.70423 | H29: 178 | I29: =VLOOKUP(B29,$CJ$97:$CP$253, 6) -> 0.7983 | J29: =H29/I29 -> 222.97382 | Q29: 178 | R29: =VLOOKUP(B29,CJ74:CV233, 12) -> 0.71 | S29: =Q29/R29 -> 250.70423 | Z29: =VLOOKUP(B29,$CG$101:$CI$257,2) -> 0.495 | AA29: =S29/Z29 -> 506.47318 | AB29: =0.5*($B31-$B28)*$G29 -> 18928.169 | AC29: =AF29/$AF$1 -> 1012.7438 | AD29: =G30 -> 506.47318 | AE29: =AC29/AD29 -> 1.9996 | AF29: =SUM(AB29:AB31) -> 50637.189 | AG29: =G29/AH29 -> 455.82586 | AH29: =$AI$1 -> 0.55 | AJ29: =AB29/AH29 -> 34414.853 | AK29: =AN29/$AF$1 -> 1841.3523 | AL29: =AD29/AH29 -> 920.86033 | AM29: =AK29/AL29 -> 1.9996 | AN29: =AF29/AH29 -> 92067.616 | AQ29: =AL29*$AP$188 -> 0 | AT29: =AL29*$AS$177 -> 0
A30: 1988 | B30: =C30-DATE(YEAR(C30),1,1)+1 -> 112 | C30: 31524 | E30: =VLOOKUP(C30,'Historic Daily flows'!$A$1:$B$37941,2) -> 7.04 | F30: 0.23 | G30: =AA29 -> 506.47318 | AB30: =((B30-B29)*G30)-((B30-B29)*(G30-G29)*0.5) -> 21579.556 | AG30: =G30/AH30 -> 920.86033 | AH30: =$AI$1 -> 0.55 | AJ30: =AB30/AH30 -> 39235.557 | AL30: =AD30/AH30 -> 0 | AN30: =AF30/AH30 -> 0
A31: 1988 | B31: =C31-DATE(YEAR(C31),1,1)+1 -> 152 | C31: 32294 | E31: =VLOOKUP(C31,'Historic Daily flows'!$A$1:$B$37941,2) -> 8.86 | G31: =AA31 -> 0 | AB31: =0.5*(B31-B30)*G30 -> 10129.464 | AG31: =G31/AH31 -> 0 | AH31: =$AI$1 -> 0.55 | AJ31: =AB31/AH31 -> 18417.207 | AL31: =AD31/AH31 -> 0 | AN31: =AF31/AH31 -> 0
